Workbook

Sheet CONSOLE
A1: CONSOLE SPACE GUDANG KANWIL JAKARTA
A2: GUDANG | B2: SPACE | C2: TERPAKAI | D2: SISA SPACE | F2: STATUS GUDANG
A3: Gudang B | B3: ='Gudang B'!G21 -> 3000 | C3: ='Gudang B'!G22 -> 3000 | D3: ='Gudang B'!G23 -> 0 | E3: ='Gudang B'!H22 | F3: ='Gudang B'!G24 -> SPACE PENUH
A4: Gudang C | B4: ='Gudang C'!G21 -> 3000 | C4: ='Gudang C'!G22 -> 3000 | D4: ='Gudang C'!G23 -> 0 | E4: =IFERROR(__xludf.DUMMYFUNCTION("'Gudang C'!H22"),"") | F4: ='Gudang C'!G24 -> SPACE PENUH
A5: Gudang D | B5: ='Gudang D'!G21 -> 3000 | C5: ='Gudang D'!G22 -> 3010 | D5: ='Gudang D'!G23 -> -10 | E5: =IFERROR(__xludf.DUMMYFUNCTION("'Gudang D'!H22"),"") | F5: ='Gudang D'!G24 -> SPACE PENUH
A6: Gudang E | B6: ='Gudang E'!G21 -> 3000 | C6: ='Gudang E'!G22 -> 2920 | D6: ='Gudang E'!G23 -> 80 | E6: =IFERROR(__xludf.DUMMYFUNCTION("'Gudang E'!H22"),"") | F6: ='Gudang E'!G24 -> SPACE TERSEDIA
A7: Gudang F | B7: ='Gudang F'!G21 -> 3000 | C7: ='Gudang F'!G22 -> 3000 | D7: ='Gudang F'!G23 -> 0 | E7: =IFERROR(__xludf.DUMMYFUNCTION("'Gudang F'!H22"),"") | F7: ='Gudang F'!G24 -> SPACE PENUH
A8: Gudang G | B8: ='Gudang G'!G21 -> 3000 | C8: ='Gudang G'!G22 -> 3000 | D8: ='Gudang G'!G23 -> 0 | E8: =IFERROR(__xludf.DUMMYFUNCTION("'Gudang G'!H22"),"") | F8: ='Gudang G'!G24 -> SPACE PENUH
A9: Gudang H | B9: ='Gudang H'!G21 -> 3000 | C9: ='Gudang H'!G22 -> 3000 | D9: ='Gudang G'!G23 -> 0 | E9: =IFERROR(__xludf.DUMMYFUNCTION("'Gudang H'!H22"),"") | F9: ='Gudang G'!G24 -> SPACE PENUH
A10: Gudang I-1 | B10: ='Gudang I-1'!G21 -> 3000 | C10: ='Gudang I-1'!G22 -> 3000 | D10: ='Gudang I-1'!G23 -> 0 | E10: =IFERROR(__xludf.DUMMYFUNCTION("'Gudang I-1'!H22"),"") | F10: ='Gudang I-1'!G24 -> SPACE PENUH
A11: Gudang I-2 | B11: ='Gudang I-2'!G21 -> 3000 | C11: ='Gudang I-2'!G22 -> 3000 | D11: ='Gudang I-2'!G23 -> 0 | E11: =IFERROR(__xludf.DUMMYFUNCTION("'Gudang I-2'!H22"),"") | F11: ='Gudang I-2'!G24 -> SPACE PENUH
A12: Gudang J-1 | B12: ='Gudang J-1'!G21 -> 1500 | C12: ='Gudang J-1'!G22 -> 1460 | D12: ='Gudang J-1'!G23 -> 40 | E12: =IFERROR(__xludf.DUMMYFUNCTION("'Gudang J-1'!H22"),"") | F12: ='Gudang J-1'!G24 -> SPACE TERSEDIA
A13: Gudang J-2 | B13: ='Gudang J-1'!G21 -> 1500 | C13: ='Gudang J-1'!G22 -> 1460 | D13: ='Gudang J-1'!G23 -> 40 | E13: =IFERROR(__xludf.DUMMYFUNCTION("'Gudang J-2'!H22"),"") | F13: ='Gudang J-1'!G24 -> SPACE TERSEDIA
A14: Gudang K | B14: ='Gudang K'!G21 -> 3000 | C14: ='Gudang K'!G22 -> 2950 | D14: ='Gudang K'!G23 -> 50 | E14: =IFERROR(__xludf.DUMMYFUNCTION("'Gudang K'!H22"),"") | F14: ='Gudang K'!G24 -> SPACE TERSEDIA
A15: Gudang L-1 | B15: ='Gudang L-1'!G21 -> 3000 | C15: ='Gudang L-1'!G22 -> 2900 | D15: ='Gudang L-1'!G23 -> 100 | E15: =IFERROR(__xludf.DUMMYFUNCTION("'Gudang L-1'!H22"),"") | F15: ='Gudang L-1'!G24 -> SPACE TERSEDIA
A16: Gudang L-2 | B16: ='Gudang L-2'!G21 -> 3000 | C16: ='Gudang L-2'!G22 -> 3000 | D16: ='Gudang L-2'!G23 -> 0 | E16: =IFERROR(__xludf.DUMMYFUNCTION("'Gudang L-2'!H22"),"") | F16: ='Gudang L-2'!G24 -> SPACE PENUH
A17: Gudang M | B17: ='Gudang M'!G21 -> 6000 | C17: ='Gudang M'!G22 -> 6000 | D17: ='Gudang M'!G23 -> 0 | E17: =IFERROR(__xludf.DUMMYFUNCTION("'Gudang M'!H22"),"") | F17: ='Gudang M'!G24 -> SPACE PENUH
A18: MP-G | B18: ='MP-G'!G21 -> 1160 | C18: ='MP-G'!G22 -> 0 | D18: ='MP-G'!G23 -> 1160 | E18: =IFERROR(__xludf.DUMMYFUNCTION("'MP-G'!H22"),"") | F18: ='MP-G'!G24 -> SPACE TERSEDIA
A19: MP-D | B19: ='MP-D'!G21 -> 1160 | C19: ='MP-D'!G22 -> 0 | D19: ='MP-D'!G23 -> 1160 | E19: =IFERROR(__xludf.DUMMYFUNCTION("'MP-D'!H22"),"") | F19: ='MP-D'!G24 -> SPACE TERSEDIA
A20: MP-J | B20: ='MP-J'!G21 -> 1160 | C20: ='MP-J'!G22 -> 0 | D20: ='MP-J'!G23 -> 1160 | E20: =IFERROR(__xludf.DUMMYFUNCTION("'MP-D'!H22"),"") | F20: ='MP-J'!G24 -> SPACE TERSEDIA
A21: MP-K | B21: ='MP-K'!G21 -> 1160 | C21: ='MP-K'!G22 -> 0 | D21: ='MP-K'!G23 -> 1160 | E21: =IFERROR(__xludf.DUMMYFUNCTION("'MP-K'!H22"),"") | F21: ='MP-K'!G24 -> SPACE TERSEDIA
A22: Open Storage | B22: ='Open Storage'!F21 -> 16972 | C22: ='Open Storage'!F22 -> 0 | D22: ='Open Storage'!F23 -> 16972 | E22: =IFERROR(__xludf.DUMMYFUNCTION("'Open Storage'!G22"),"") | F22: ='Open Storage'!F24 -> SPACE TERSEDIA

Sheet Denah
AJ1: OPEN STORAGE
U2: 45
H3: 43 | I3: M 2 | S3: 44 | AJ3: 1 | AK3: 80 X 17 | AL3: 1,360 m²
AJ4: 2 | AK4: 60 X 7 | AL4: 420 m²
AJ5: 3 | AK5: 60 X 7 | AL5: 420 m²
AJ6: 4 | AK6: 60 X 7 | AL6: 420 m²
I7: M 1 | V7: B | AF7: 46 | AH7: 36 | AJ7: 5 | AK7: 30 X 7 | AL7: 210 m²
AJ8: 6 | AK8: 15 X 13 | AL8: 195 m²
AJ9: 7 | AK9: 15 X 11 | AL9: 165 m²
AJ10: 8 | AK10: 13 X 23 | AL10: 299 m²
AJ11: 9 | AK11: 15 X 11 | AL11: 165 m²
I12: 37 | K12: 38 | M12: 39 | P12: 40 | R12: 41 | V12: MP-B | AJ12: 10 | AK12: 13 X 13 | AL12: 169 m²
AJ13: 11 | AK13: 24 X 7 | AL13: 168 m²
U14: 42 | V14: C | AJ14: 12 | AK14: 60 X 7 | AL14: 420 m²
B15: COLD STORAGE | E15: COLD STORAGE | AJ15: 13 | AK15: 60 X 7 | AL15: 420 m²
H16: 29 | I16: L 2 | S16: 30 | AJ16: 14 | AK16: 54 X 7 | AL16: 378 m²
AJ17: 15 | AK17: 22 X 13 | AL17: 286 m²
AJ18: 16 | AK18: 22 X 11 | AL18: 242 m²
V19: 31 | X19: 32 | Z19: 33 | AC19: 34 | AE19: 35 | AJ19: 17 | AK19: 22 X 23 | AL19: 253 m²
I20: L 1 | AJ20: 18 | AK20: 22 X 11 | AL20: 242 m²
AJ21: 19 | AK21: 22 X 13 | AL21: 286 m²
AJ22: 20 | AK22: 30 X 7 | AL22: 210 m²
U23: 28 | V23: D | AJ23: 21 | AK23: 150 X 7 | AL23: 1,050 m²
AJ24: 22 | AK24: 15 X 13 | AL24: 195 m²
D25: 22 | I25: 23 | K25: 24 | M25: 25 | P25: 26 | R25: 27 | AJ25: 23 | AK25: 15 X 11 | AL25: 165 m²
AJ26: 24 | AK26: 15 X 13 | AL26: 195 m²
AJ27: 25 | AK27: 30 X 7 | AL27: 210 m²
V28: MP-D | AH28: 21 | AJ28: 26 | AK28: 60 X 7 | AL28: 420 m²
D29: K 2 | F29: 12 | H29: 13 | I29: I 2 | S29: 14 | AJ29: 27 | AK29: 22 X 13 | AL29: 286 m²
U30: 20 | V30: E | AJ30: 28 | AK30: 22 X 11 | AL30: 242 m²
AJ31: 29 | AK31: 22 X 23 | AL31: 506 m²
AJ32: 30 | AK32: 22 X 11 | AL32: 242 m²
D33: K 1 | I33: I 1 | AJ33: 31 | AK33: 22 X 13 | AL33: 286 m²
AJ34: 32 | AK34: 75 X 7 | AL34: 525 m²
V35: 15 | X35: 16 | Z35: 17 | AC35: 18 | AE35: 19 | AJ35: 33 | AK35: 15 X 13 | AL35: 195 m²
AJ36: 34 | AK36: 15 X 11 | AL36: 165 m²
AJ37: 35 | AK37: 15 X 23 | AL37: 345 m²
I38: 6 | K38: 7 | M38: 8 | P38: 9 | R38: 10 | AJ38: 36 | AK38: 15 X 11 | AL38: 165 m²
D39: MP-K | U39: 11 | V39: F | AJ39: 37 | AK39: 15 X 23 | AL39: 345 m²
AJ40: 38 | AK40: 15 X 23 | AL40: 345 m²
...

Sheet Kontrak
A1: No. | B1: PELANGGAN | C1: LOKASI | D1: LUAS | E1: JENIS | F1: Periode Kontrak
F2: Mulai | G2: Selesai
A3: 1 | B3: PT. BINTANG RAMA MANDIRI | C3: B | D3: 1535 | E3: KO | F3: 46113 | G3: 46203
A4: 2 | B4: PT. BINTANG RAMA MANDIRI | C4: B | D4: 1535 | E4: KO | F4: 46204 | G4: 46295
A5: 3 | B5: PT. JOHNSON AND JOHNSON INDONESIA TWO | C5: B | D5: 900 | E5: KONTRAK | F5: 46112 | G5: 47207
A6: 4 | B6: PT. JIVA AGRICULTURE INDONESIA | C6: B | D6: 37 | E6: KO | F6: 46084 | G6: 46175
A7: 5 | B7: PT WAHANA ANAK INDONESIA | C7: B | D7: 292 | E7: KO | F7: 46023 | G7: 46203
A8: 6 | B8: PT. SURI NUSANTARA JAYA | C8: B | D8: 1 | E8: KO | F8: 46113 | G8: 46203
A9: 7 | B9: PT. ANUGRAH TRANS GEMILANG (Ex. PT. ANUGRAH ANDALAS AGUNG) | C9: B | D9: 13 | E9: KO | F9: 46113 | G9: 46203
A10: 8 | B10: PT. PANCA TRANS LOGISTICS | C10: B | D10: 13 | E10: KO | F10: 46117 | G10: 46207
A11: 9 | B11: PT. CAMAR MITRA LANGGENG | C11: B | D11: 15 | E11: KO | F11: 46113 | G11: 46203
A12: 10 | B12: PT. SARANA GEMILANG INDONESIA | C12: B | D12: 8 | E12: KO | F12: 46113 | G12: 46203
A13: 11 | B13: RAYMON YUNANTA (PERORANGAN) | C13: B | D13: 9 | E13: KO | F13: 46116 | G13: 46206
A14: 12 | B14: PT. LOGWIN AIR & OCEAN INDONESIA | C14: B | D14: 3489 | E14: KO | F14: 46054 | G14: 46387
... A78: 76 | B78: PT. AROMA PRIMA INDONESIA | C78: J-1 | D78: 100 | E78: KONTRAK | F78: 45839 | G78: 46203
A79: 77 | B79: PT. KIANG DENTAL | C79: J-1 | D79: TENTATIVE | E79: KO | F79: 46113 | G79: 46203
A80: 78 | B80: PT. BANGUN BERKAT BERSAMA | C80: L | D80: 50 | E80: KO | F80: 46080 | G80: 46168
A81: 79 | B81: PT. LUXASIA INDONESIA | C81: L | D81: 200 | E81: KO | F81: 46151 | G81: 46242
A82: 80 | B82: CV. RESTU SEMESTA BUMI | C82: L | D82: 50 | E82: KO | F82: 46151 | G82: 46242
A83: 81 | B83: CV CEMERLANG TERUS JAYA | C83: L | D83: 200 | E83: KO | F83: 46180 | G83: 46209
A84: 82 | B84: CV CEMERLANG TERUS JAYA | C84: L | D84: 100 | E84: KO | F84: 46113 | G84: 46203
A85: 83 | B85: PT. SAMUDRA PERMATA MOTOKARZ | C85: L | D85: 150 | E85: KO | F85: 46157 | G85: 46248
A86: 84 | B86: PT. BANGUN BERKAT BERSAMA | C86: L | D86: 100 | E86: KONTRAK | F86: 45946 | G86: 46310
A87: 85 | B87: RUBEN KRISTANTO (PERORANGAN) | C87: L | D87: 100 | E87: KO | F87: 46107 | G87: 46198
A88: 86 | B88: PT. BANGUN BERKAT BERSAMA | C88: L | D88: 50 | E88: KO | F88: 46169 | G88: 46260
A89: 87 | B89: PT. BANGUN BERKAT BERSAMA | C89: L | D89: 50 | E89: KO | F89: 46130 | G89: 46220
A90: 88 | B90: PT. ADICENTRA AROMETAL | C90: OS | D90: 100 | E90: KO | F90: 46113 | G90: 46203
A91: 89 | B91: PT. ADICENTRA AROMETAL | C91: OS | D91: 30 | E91: KO | F91: 46113 | G91: 46203
... A97: 95 | B97: PT. CLASSIC FINE FOODS INDONESIA | C97: OS | D97: 110 | E97: KONTRAK | F97: 45337 | G97: 46432

Sheet Gudang B
A1: LAYOUT GUDANG B
A3: AREA | K3: 30 M
B4: PINTU 1 | D4: PINTU 2 | G4: PINTU 3 | I4: PINTU 4
A5: PT. JOHNSON AND JOHNSON INDONESIA TWO | C5: RMC | E5: RMC | F5: RMC | H5: RMC | J5: RMC
A6: PT. JOHNSON AND JOHNSON INDONESIA TWO | C6: RMC | E6: RMC | F6: RMC | H6: RMC | J6: RMC
A7: PT. JOHNSON AND JOHNSON INDONESIA TWO | C7: PT. JOHNSON AND JOHNSON INDONESIA TWO | E7: RMC | F7: RMC | H7: RMC | J7: RMC
A8: PT. JOHNSON AND JOHNSON INDONESIA TWO | C8: PT. JOHNSON AND JOHNSON INDONESIA TWO | E8: RMC | F8: RMC | H8: RMC | J8: RMC
A9: PT. JOHNSON AND JOHNSON INDONESIA TWO | C9: PT. JOHNSON AND JOHNSON INDONESIA TWO | E9: RMC | F9: RMC | H9: RMC | J9: RMC
A10: PT. JOHNSON AND JOHNSON INDONESIA TWO | C10: PT. JOHNSON AND JOHNSON INDONESIA TWO | E10: RMC | F10: RMC | H10: RMC | J10: RMC
A11: PT. JOHNSON AND JOHNSON INDONESIA TWO | C11: PT. JOHNSON AND JOHNSON INDONESIA TWO | E11: RMC | F11: RMC | H11: RMC | J11: RMC
A12: PT. JOHNSON AND JOHNSON INDONESIA TWO | C12: PT. JOHNSON AND JOHNSON INDONESIA TWO | E12: RMC | F12: RMC | H12: RMC | J12: RMC
A13: PT. JOHNSON AND JOHNSON INDONESIA TWO | C13: PT. JOHNSON AND JOHNSON INDONESIA TWO | E13: RMC | F13: RMC | H13: RMC | J13: RMC
A14: PT. JOHNSON AND JOHNSON INDONESIA TWO | C14: PT. JOHNSON AND JOHNSON INDONESIA TWO | E14: RMC | F14: RMC | H14: RMC | J14: RMC
B15: PINTU 1 | D15: PINTU 2 | G15: PINTU 3 | I15: PINTU 4
A16: AREA
A17: 100 M
A20: CUSTOMER | C20: SPACE m² | D20: ADDITIONAL m² | E20: JENIS BARANG | F20: INFORMASI GUDANG
A21: =IFERROR(__xludf.DUMMYFUNCTION("IFERROR( UNIQUE( FILTER( {A5:A14;C5:C14;E5:E14;F5:F14;H5:H14;J5:J14 }, {A5:A14;C5:C14;E5:E14;F5:F14;H5:H14;J5:J14}<>"""" ) ), """" )"),"PT. JOHNSON AND JOHNSON INDONESIA TWO") -> PT. JOHNSON AND JOHNSON INDONESIA TWO | C21: =IF(A21="","",COUNTIF($A$5:$J$14,A21)*50 + IFERROR(D23,0)) -> 900 | F21: Space Gudang | G21: 3000
A22: =IFERROR(__xludf.DUMMYFUNCTION("""COMPUTED_VALUE"""),"RMC") -> RMC | C22: =IF(A22="","",COUNTIF($A$5:$J$14,A22)*50 + IFERROR(D24,0)) -> 2100 | F22: Total Terpakai | G22: =SUM(C21:C1014) -> 3000 | H22: =IFERROR(__xludf.DUMMYFUNCTION("IF( SUM(C21:C1014)<=2100, SPARKLINE(SUM(C21:C1014),{""charttype"",""bar"";""max"",3000;""color1"",""#2ECC71""}), IF( SUM(C21:C1014)<=2700, SPARKLINE(SUM(C21:C1014),{""charttype"",""bar"";""max"",3000;""color1"",""#F1C40F""}), SPARKLINE(SUM(C21:C1014),{""c"&"harttype"",""bar"";""max"",3000;""color1"",""#E74C3C""}) )) "),"")
C23: =IF(A23="","",COUNTIF($A$5:$J$14,A23)*50 + IFERROR(D25,0)) | F23: Sisa Space | G23: =G21-G22 -> 0
C24: =IF(A24="","",COUNTIF($A$5:$J$14,A24)*50 + IFERROR(D26,0)) | F24: Status Gudang | G24: =IF(G23<=0,"SPACE PENUH","SPACE TERSEDIA") -> SPACE PENUH
C25: =IF(A25="","",COUNTIF($A$5:$J$14,A25)*50 + IFERROR(D27,0))
C26: =IF(A26="","",COUNTIF($A$5:$J$14,A26)*50 + IFERROR(D28,0))
C27: =IF(A27="","",COUNTIF($A$5:$J$14,A27)*50 + IFERROR(D29,0))
C28: =IF(A28="","",COUNTIF($A$5:$J$14,A28)*50 + IFERROR(D30,0))
C29: =IF(A29="","",COUNTIF($A$5:$J$14,A29)*50 + IFERROR(D31,0))
C30: =IF(A30="","",COUNTIF($A$5:$J$14,A30)*50 + IFERROR(D32,0))
C31: =IF(A31="","",COUNTIF($A$5:$J$14,A31)*50 + IFERROR(D33,0))
C32: =IF(A32="","",COUNTIF($A$5:$J$14,A32)*50 + IFERROR(D34,0))
C33: =IF(A33="","",COUNTIF($A$5:$J$14,A33)*50 + IFERROR(D35,0))
C34: =IF(A34="","",COUNTIF($A$5:$J$14,A34)*50 + IFERROR(D36,0))
C35: =IF(A35="","",COUNTIF($A$5:$J$14,A35)*50 + IFERROR(D37,0))
C36: =IF(A36="","",COUNTIF($A$5:$J$14,A36)*50 + IFERROR(D38,0))
... C40: =IF(A40="","",COUNTIF($A$5:$J$14,A40)*50 + IFERROR(D42,0))
C41: =IF(A41="","",COUNTIF($A$5:$J$10,A41)*50 + IFERROR(D41,0))
C42: =IF(A42="","",COUNTIF($A$5:$J$10,A42)*50 + IFERROR(D42,0))
C43: =IF(A43="","",COUNTIF($A$5:$J$10,A43)*50 + IFERROR(D43,0))
C44: =IF(A44="","",COUNTIF($A$5:$J$10,A44)*50 + IFERROR(D44,0))
C45: =IF(A45="","",COUNTIF($A$5:$J$10,A45)*50 + IFERROR(D45,0))
C46: =IF(A46="","",COUNTIF($A$5:$J$10,A46)*50 + IFERROR(D46,0))
...

Sheet Gudang C
A1: LAYOUT GUDANG C
A3: AREA | K3: 30 M
B4: PINTU 1 | D4: PINTU 2 | G4: PINTU 3 | I4: PINTU 4
A5: PT. CLASSIC FINE FOOD | C5: PT. CLASSIC FINE FOOD | E5: PT. CLASSIC FINE FOOD | F5: PT. CLASSIC FINE FOOD | H5: PT. CLASSIC FINE FOOD | J5: PT. LUXCHEM INDONESIA
A6: PT. CLASSIC FINE FOOD | C6: PT. CLASSIC FINE FOOD | E6: PT. CLASSIC FINE FOOD | F6: PT. CLASSIC FINE FOOD | H6: PT. CLASSIC FINE FOOD | J6: PT. LUXCHEM INDONESIA
A7: PT. CLASSIC FINE FOOD | C7: PT. CLASSIC FINE FOOD | E7: PT. CLASSIC FINE FOOD | F7: PT. CLASSIC FINE FOOD | H7: PT. CLASSIC FINE FOOD | J7: PT. LUXCHEM INDONESIA
A8: PT. CLASSIC FINE FOOD | C8: PT. CLASSIC FINE FOOD | E8: PT. CLASSIC FINE FOOD | F8: PT. CLASSIC FINE FOOD | H8: PT. CLASSIC FINE FOOD | J8: PT. LUXCHEM INDONESIA
A9: PT. CLASSIC FINE FOOD | C9: PT. CLASSIC FINE FOOD | E9: PT. CLASSIC FINE FOOD | F9: PT. CLASSIC FINE FOOD | H9: PT. CLASSIC FINE FOOD | J9: PT. LUXCHEM INDONESIA
A10: PT. CLASSIC FINE FOOD | C10: PT. CLASSIC FINE FOOD | E10: PT. CLASSIC FINE FOOD | F10: PT. CLASSIC FINE FOOD | H10: PT. LUXCHEM INDONESIA | J10: PT. LUXCHEM INDONESIA
A11: PT. CLASSIC FINE FOOD | C11: PT. CLASSIC FINE FOOD | E11: PT. CLASSIC FINE FOOD | F11: PT. CLASSIC FINE FOOD | H11: PT. LUXCHEM INDONESIA | J11: PT. LUXCHEM INDONESIA
A12: PT. CLASSIC FINE FOOD | C12: PT. CLASSIC FINE FOOD | E12: PT. CLASSIC FINE FOOD | F12: PT. CLASSIC FINE FOOD | H12: PT. LUXCHEM INDONESIA | J12: PT. LUXCHEM INDONESIA
A13: PT. CLASSIC FINE FOOD | C13: PT. CLASSIC FINE FOOD | E13: PT. CLASSIC FINE FOOD | F13: PT. CLASSIC FINE FOOD | H13: PT. LUXCHEM INDONESIA | J13: PT. LUXCHEM INDONESIA
A14: PT. CLASSIC FINE FOOD | C14: PT. CLASSIC FINE FOOD | E14: PT. CLASSIC FINE FOOD | F14: PT. CLASSIC FINE FOOD | H14: PT. LUXCHEM INDONESIA | J14: PT. LUXCHEM INDONESIA
B15: PINTU 1 | D15: PINTU 2 | G15: PINTU 3 | I15: PINTU 4
A16: AREA
A17: 100 M
A20: CUSTOMER | C20: SPACE m² | D20: ADDITIONAL m² | E20: JENIS BARANG | F20: INFORMASI GUDANG
A21: =IFERROR(__xludf.DUMMYFUNCTION("IFERROR( UNIQUE( FILTER( {A5:A14;C5:C14;E5:E14;F5:F14;H5:H14;J5:J14 }, {A5:A14;C5:C14;E5:E14;F5:F14;H5:H14;J5:J14}<>"""" ) ), """" )"),"PT. CLASSIC FINE FOOD") -> PT. CLASSIC FINE FOOD | C21: =IF(A21="","",COUNTIF($A$5:$J$14,A21)*50 + IFERROR(D23,0)) -> 2250 | F21: Space Gudang | G21: 3000
A22: =IFERROR(__xludf.DUMMYFUNCTION("""COMPUTED_VALUE"""),"PT. LUXCHEM INDONESIA") -> PT. LUXCHEM INDONESIA | C22: =IF(A22="","",COUNTIF($A$5:$J$14,A22)*50 + IFERROR(D24,0)) -> 750 | F22: Total Terpakai | G22: =SUM(C21:C1014) -> 3000 | H22: =IFERROR(__xludf.DUMMYFUNCTION("IF( SUM(C21:C1014)<=2100, SPARKLINE(SUM(C21:C1014),{""charttype"",""bar"";""max"",3000;""color1"",""#2ECC71""}), IF( SUM(C21:C1014)<=2700, SPARKLINE(SUM(C21:C1014),{""charttype"",""bar"";""max"",3000;""color1"",""#F1C40F""}), SPARKLINE(SUM(C21:C1014),{""c"&"harttype"",""bar"";""max"",3000;""color1"",""#E74C3C""}) )) "),"")
C23: =IF(A23="","",COUNTIF($A$5:$J$14,A23)*50 + IFERROR(D25,0)) | F23: Sisa Space | G23: =G21-G22 -> 0
C24: =IF(A24="","",COUNTIF($A$5:$J$14,A24)*50 + IFERROR(D26,0)) | F24: Status Gudang | G24: =IF(G23<=0,"SPACE PENUH","SPACE TERSEDIA") -> SPACE PENUH
C25: =IF(A25="","",COUNTIF($A$5:$J$14,A25)*50 + IFERROR(D27,0))
C26: =IF(A26="","",COUNTIF($A$5:$J$14,A26)*50 + IFERROR(D28,0))
C27: =IF(A27="","",COUNTIF($A$5:$J$14,A27)*50 + IFERROR(D29,0))
C28: =IF(A28="","",COUNTIF($A$5:$J$14,A28)*50 + IFERROR(D30,0))
C29: =IF(A29="","",COUNTIF($A$5:$J$14,A29)*50 + IFERROR(D31,0))
C30: =IF(A30="","",COUNTIF($A$5:$J$14,A30)*50 + IFERROR(D32,0))
C31: =IF(A31="","",COUNTIF($A$5:$J$14,A31)*50 + IFERROR(D33,0))
C32: =IF(A32="","",COUNTIF($A$5:$J$14,A32)*50 + IFERROR(D34,0))
C33: =IF(A33="","",COUNTIF($A$5:$J$14,A33)*50 + IFERROR(D35,0))
C34: =IF(A34="","",COUNTIF($A$5:$J$14,A34)*50 + IFERROR(D36,0))
C35: =IF(A35="","",COUNTIF($A$5:$J$14,A35)*50 + IFERROR(D37,0))
C36: =IF(A36="","",COUNTIF($A$5:$J$14,A36)*50 + IFERROR(D38,0))
... C40: =IF(A40="","",COUNTIF($A$5:$J$14,A40)*50 + IFERROR(D42,0))
C41: =IF(A41="","",COUNTIF($A$5:$J$10,A41)*50 + IFERROR(D41,0))
C42: =IF(A42="","",COUNTIF($A$5:$J$10,A42)*50 + IFERROR(D42,0))
C43: =IF(A43="","",COUNTIF($A$5:$J$10,A43)*50 + IFERROR(D43,0))
C44: =IF(A44="","",COUNTIF($A$5:$J$10,A44)*50 + IFERROR(D44,0))
C45: =IF(A45="","",COUNTIF($A$5:$J$10,A45)*50 + IFERROR(D45,0))
C46: =IF(A46="","",COUNTIF($A$5:$J$10,A46)*50 + IFERROR(D46,0))
...

Sheet Gudang D
A1: LAYOUT GUDANG D
A3: AREA | K3: 30 M
B4: PINTU 1 | D4: PINTU 2 | G4: PINTU 3 | I4: PINTU 4
A5: PT.DHANUSH | C5: PT.PRIMACOMM | E5: PT.CIBES | F5: PT.CIBES | H5: PT.ARTHA MEGA INFRA | J5: PERTAMINA PETROCHEMICAL
A6: PT.DHANUSH | C6: PT.PRIMACOMM | E6: PT.CIBES | F6: PT.CIBES | H6: PT.ARTHA MEGA INFRA | J6: PERTAMINA PETROCHEMICAL
A7: PT.DHANUSH | C7: PT.HITE JINRO | E7: PT.CIBES | F7: PT.CIBES | H7: KSU/POMAL | J7: PERTAMINA PETROCHEMICAL
A8: PT.DHANUSH | C8: PT.HITE JINRO | E8: PT.CIBES | F8: PT.CIBES | H8: KSU/POMAL | J8: PERTAMINA PETROCHEMICAL
A9: PT.DHANUSH | C9: PT. LANGIT BIRU | E9: PT.CIBES | F9: PT.CIBES | H9: PT.PRIMA PUTRA MAS | J9: PERTAMINA PETROCHEMICAL
A10: PT.DHANUSH | C10: PT. LANGIT BIRU | E10: PT.CIBES | F10: PT.CIBES | H10: PT.PRIMA PUTRA MAS | J10: PERTAMINA PETROCHEMICAL
A11: PT.DHANUSH | C11: PT.CIBES | E11: PT.CIBES | F11: PT.CIBES | H11: DIVAS VINTAGE | J11: PERTAMINA PETROCHEMICAL
A12: PT.DHANUSH | C12: PT.CIBES | E12: PT.CIBES | F12: PERTAMINA PETROCHEMICAL | H12: PERTAMINA PETROCHEMICAL | J12: PERTAMINA PETROCHEMICAL
A13: PT.DHANUSH | C13: PT.CIBES | E13: PT.CIBES | F13: PERTAMINA PETROCHEMICAL | H13: PERTAMINA PETROCHEMICAL | J13: PERTAMINA PETROCHEMICAL
A14: PT.PRIMACOMM | C14: PT.CIBES | E14: PT.CIBES | F14: PERTAMINA PETROCHEMICAL | H14: PERTAMINA PETROCHEMICAL | J14: PERTAMINA PETROCHEMICAL
B15: PINTU 1 | D15: PINTU 2 | G15: PINTU 3 | I15: PINTU 4
A16: AREA
A17: 100 M
A20: CUSTOMER | C20: SPACE m² | D20: ADDITIONAL m² | E20: JENIS BARANG | F20: INFORMASI GUDANG
A21: =IFERROR(__xludf.DUMMYFUNCTION("IFERROR( UNIQUE( FILTER( {A5:A14;C5:C14;E5:E14;F5:F14;H5:H14;J5:J14 }, {A5:A14;C5:C14;E5:E14;F5:F14;H5:H14;J5:J14}<>"""" ) ), """" )"),"PT.DHANUSH") -> PT.DHANUSH | C21: =IF(A21="","",COUNTIF($A$5:$J$14,A21)*50 + IFERROR(D21,0)) -> 450 | F21: Space Gudang | G21: 3000
A22: =IFERROR(__xludf.DUMMYFUNCTION("""COMPUTED_VALUE"""),"PT.PRIMACOMM") -> PT.PRIMACOMM | C22: =IF(A22="","",COUNTIF($A$5:$J$14,A22)*50 + IFERROR(D22,0)) -> 130 | D22: -20 | F22: Total Terpakai | G22: =SUM(C21:C1014) -> 3010 | H22: =IFERROR(__xludf.DUMMYFUNCTION("IF( SUM(C21:C1014)<=2100, SPARKLINE(SUM(C21:C1014),{""charttype"",""bar"";""max"",3000;""color1"",""#2ECC71""}), IF( SUM(C21:C1014)<=2700, SPARKLINE(SUM(C21:C1014),{""charttype"",""bar"";""max"",3000;""color1"",""#F1C40F""}), SPARKLINE(SUM(C21:C1014),{""c"&"harttype"",""bar"";""max"",3000;""color1"",""#E74C3C""}) )) "),"")
A23: =IFERROR(__xludf.DUMMYFUNCTION("""COMPUTED_VALUE"""),"PT.HITE JINRO") -> PT.HITE JINRO | C23: =IF(A23="","",COUNTIF($A$5:$J$14,A23)*50 + IFERROR(D23,0)) -> 100 | F23: Sisa Space | G23: =G21-G22 -> -10
A24: =IFERROR(__xludf.DUMMYFUNCTION("""COMPUTED_VALUE"""),"PT. LANGIT BIRU") -> PT. LANGIT BIRU | C24: =IF(A24="","",COUNTIF($A$5:$J$14,A24)*50 + IFERROR(D24,0)) -> 100 | F24: Status Gudang | G24: =IF(G23<=0,"SPACE PENUH","SPACE TERSEDIA") -> SPACE PENUH
A25: =IFERROR(__xludf.DUMMYFUNCTION("""COMPUTED_VALUE"""),"PT.CIBES") -> PT.CIBES | C25: =IF(A25="","",COUNTIF($A$5:$J$14,A25)*50 + IFERROR(D25,0)) -> 1080 | D25: 30
A26: =IFERROR(__xludf.DUMMYFUNCTION("""COMPUTED_VALUE"""),"PERTAMINA PETROCHEMICAL ") -> PERTAMINA PETROCHEMICAL | C26: =IF(A26="","",COUNTIF($A$5:$J$14,A26)*50 + IFERROR(D26,0)) -> 800
A27: =IFERROR(__xludf.DUMMYFUNCTION("""COMPUTED_VALUE"""),"PT.ARTHA MEGA INFRA") -> PT.ARTHA MEGA INFRA | C27: =IF(A27="","",COUNTIF($A$5:$J$14,A27)*50 + IFERROR(D27,0)) -> 100
A28: =IFERROR(__xludf.DUMMYFUNCTION("""COMPUTED_VALUE"""),"KSU/POMAL ") -> KSU/POMAL | C28: =IF(A28="","",COUNTIF($A$5:$J$14,A28)*50 + IFERROR(D28,0)) -> 125 | D28: 25
A29: =IFERROR(__xludf.DUMMYFUNCTION("""COMPUTED_VALUE"""),"PT.PRIMA PUTRA MAS") -> PT.PRIMA PUTRA MAS | C29: =IF(A29="","",COUNTIF($A$5:$J$14,A29)*50 + IFERROR(D29,0)) -> 100
A30: =IFERROR(__xludf.DUMMYFUNCTION("""COMPUTED_VALUE"""),"DIVAS VINTAGE") -> DIVAS VINTAGE | C30: =IF(A30="","",COUNTIF($A$5:$J$14,A30)*50 + IFERROR(D30,0)) -> 25 | D30: -25
C31: =IF(A31="","",COUNTIF($A$5:$J$14,A31)*50 + IFERROR(D31,0))
C32: =IF(A32="","",COUNTIF($A$5:$J$14,A32)*50 + IFERROR(D32,0))
C33: =IF(A33="","",COUNTIF($A$5:$J$14,A33)*50 + IFERROR(D33,0))
C34: =IF(A34="","",COUNTIF($A$5:$J$14,A34)*50 + IFERROR(D34,0))
C35: =IF(A35="","",COUNTIF($A$5:$J$14,A35)*50 + IFERROR(D35,0))
C36: =IF(A36="","",COUNTIF($A$5:$J$14,A36)*50 + IFERROR(D36,0))
C37: =IF(A37="","",COUNTIF($A$5:$J$14,A37)*50 + IFERROR(D37,0))
C38: =IF(A38="","",COUNTIF($A$5:$J$14,A38)*50 + IFERROR(D38,0))
C39: =IF(A39="","",COUNTIF($A$5:$J$14,A39)*50 + IFERROR(D41,0))
C40: =IF(A40="","",COUNTIF($A$5:$J$14,A40)*50 + IFERROR(D42,0))
C41: =IF(A41="","",COUNTIF($A$5:$J$10,A41)*50 + IFERROR(D41,0))
C42: =IF(A42="","",COUNTIF($A$5:$J$10,A42)*50 + IFERROR(D42,0))
C43: =IF(A43="","",COUNTIF($A$5:$J$10,A43)*50 + IFERROR(D43,0))
...

Sheet Gudang E
A1: LAYOUT GUDANG E
A3: AREA | K3: 30 M
B4: PINTU 1 | D4: PINTU 2 | G4: PINTU 3 | I4: PINTU 4
A5: PT. VALSPAR INDONESIA | C5: PT. SEGORO INTERNATIONAL | D5: PT. SEGORO INTERNATIONAL | E5: PT. SEGORO INTERNATIONAL | F5: PT. BEST ENERGY | H5: PT. INTER KREATIV LIFT INDONESIA | J5: PT. MEGA MART
A6: PT. VALSPAR INDONESIA | C6: PT. SEGORO INTERNATIONAL | E6: PT. SEGORO INTERNATIONAL | F6: PT. BEST ENERGY | H6: PT. INTER KREATIV LIFT INDONESIA | J6: PT. GUNUNG PADU PRIMAKASA
A7: PT. VALSPAR INDONESIA | C7: PT. SEGORO INTERNATIONAL | E7: PT. SEGORO INTERNATIONAL | F7: PT. BEST ENERGY | H7: PT. TOTAL PETROKEM | J7: PT. GUNUNG PADU PRIMAKASA | M7: =3*15 -> 45 | N7: =M7*10 -> 450 | O7: =N7*6 -> 2700 | P7: =(2.5*30)*4 -> 300 | Q7: =O7+P7 -> 3000
A8: PT. VALSPAR INDONESIA | C8: PT. SEGORO INTERNATIONAL | E8: PT. SEGORO INTERNATIONAL | F8: PT. BEST ENERGY | H8: PT. TOTAL PETROKEM | J8: PT. GUNUNG PADU PRIMAKASA
A9: PT. VALSPAR INDONESIA | C9: PT. SEGORO INTERNATIONAL | E9: PT. SEGORO INTERNATIONAL | F9: PT. VALSPAR INDONESIA | H9: PT. SEGORO INTERNATIONAL | J9: PT. INTER KREATIV LIFT INDONESIA
A10: PT. VALSPAR INDONESIA | C10: PT. SEGORO INTERNATIONAL | E10: PT. SEGORO INTERNATIONAL | F10: PT. VALSPAR INDONESIA | H10: PT. SEGORO INTERNATIONAL | J10: PT. PYROTEK INDONESIA
A11: PT. VALSPAR INDONESIA | C11: PT. SEGORO INTERNATIONAL | E11: PT. SEGORO INTERNATIONAL | F11: PT. VALSPAR INDONESIA | J11: PT. PYROTEK INDONESIA
A12: PT. VALSPAR INDONESIA | C12: PT. SEGORO INTERNATIONAL | E12: PT. TIRTA MAS KIMIA | F12: PT. VALSPAR INDONESIA | H12: PT. TECSOM FLOORING INDONESIA | J12: PT. PYROTEK INDONESIA
A13: PT. VALSPAR INDONESIA | C13: PT. TOTAL PETROKEM | E13: PT. TIRTA MAS KIMIA | F13: PT. VALSPAR INDONESIA | H13: PT. TECSOM FLOORING INDONESIA | J13: PT. ABADI KIMIA INTERNUSA
A14: PT. VALSPAR INDONESIA | C14: PT. TOTAL PETROKEM | E14: PT. TIRTA MAS KIMIA | F14: PT. VALSPAR INDONESIA | H14: PT. TECSOM FLOORING INDONESIA | J14: PT. ABADI KIMIA INTERNUSA
B15: PINTU 1 | D15: PINTU 2 | G15: PINTU 3 | I15: PINTU 4
A16: AREA
A17: 100 M
A20: CUSTOMER | C20: SPACE m² | D20: ADDITIONAL m² | E20: JENIS BARANG | F20: INFORMASI GUDANG
A21: =IFERROR(__xludf.DUMMYFUNCTION("IFERROR( UNIQUE( FILTER( {A5:A14;C5:C14;E5:E14;F5:F14;H5:H14;J5:J14 }, {A5:A14;C5:C14;E5:E14;F5:F14;H5:H14;J5:J14}<>"""" ) ), """" )"),"PT. VALSPAR INDONESIA") -> PT. VALSPAR INDONESIA | C21: =IF(A21="","",COUNTIF($A$5:$J$14,A21)*45 + IFERROR(D21,0)) -> 800 | D21: 80 | F21: Space Gudang | G21: 3000 | I21: =G21*80% -> 2400
A22: =IFERROR(__xludf.DUMMYFUNCTION("""COMPUTED_VALUE"""),"PT. SEGORO INTERNATIONAL ") -> PT. SEGORO INTERNATIONAL | C22: =IF(A22="","",COUNTIF($A$5:$J$14,A22)*45 + IFERROR(D22,0)) -> 835 | D22: 25 | F22: Total Terpakai | G22: =SUM(C21:C1014) -> 2920 | H22: =IFERROR(__xludf.DUMMYFUNCTION("IF( SUM(C21:C1014)<=2100, SPARKLINE(SUM(C21:C1014),{""charttype"",""bar"";""max"",3000;""color1"",""#2ECC71""}), IF( SUM(C21:C1014)<=2700, SPARKLINE(SUM(C21:C1014),{""charttype"",""bar"";""max"",3000;""color1"",""#F1C40F""}), SPARKLINE(SUM(C21:C1014),{""c"&"harttype"",""bar"";""max"",3000;""color1"",""#E74C3C""}) )) "),"")
A23: =IFERROR(__xludf.DUMMYFUNCTION("""COMPUTED_VALUE"""),"PT. TOTAL PETROKEM") -> PT. TOTAL PETROKEM | C23: =IF(A23="","",COUNTIF($A$5:$J$14,A23)*45 + IFERROR(D23,0)) -> 200 | D23: 20 | F23: Sisa Space | G23: =G21-G22 -> 80
A24: =IFERROR(__xludf.DUMMYFUNCTION("""COMPUTED_VALUE"""),"PT. TIRTA MAS KIMIA") -> PT. TIRTA MAS KIMIA | C24: =IF(A24="","",COUNTIF($A$5:$J$14,A24)*45 + IFERROR(D24,0)) -> 160 | D24: 25 | F24: Status Gudang | G24: =IF(G23<=0,"SPACE PENUH","SPACE TERSEDIA") -> SPACE TERSEDIA
A25: =IFERROR(__xludf.DUMMYFUNCTION("""COMPUTED_VALUE"""),"PT. BEST ENERGY") -> PT. BEST ENERGY | C25: =IF(A25="","",COUNTIF($A$5:$J$14,A25)*45 + IFERROR(D25,0)) -> 200 | D25: 20
A26: =IFERROR(__xludf.DUMMYFUNCTION("""COMPUTED_VALUE"""),"PT. INTER KREATIV LIFT INDONESIA") -> PT. INTER KREATIV LIFT INDONESIA | C26: =IF(A26="","",COUNTIF($A$5:$J$14,A26)*45 + IFERROR(D26,0)) -> 150 | D26: 15
A27: =IFERROR(__xludf.DUMMYFUNCTION("""COMPUTED_VALUE"""),"PT. TECSOM FLOORING INDONESIA") -> PT. TECSOM FLOORING INDONESIA | C27: =IF(A27="","",COUNTIF($A$5:$J$14,A27)*45 + IFERROR(D27,0)) -> 150 | D27: 15
A28: =IFERROR(__xludf.DUMMYFUNCTION("""COMPUTED_VALUE"""),"PT. MEGA MART") -> PT. MEGA MART | C28: =IF(A28="","",COUNTIF($A$5:$J$14,A28)*45 + IFERROR(D28,0)) -> 25 | D28: -20
A29: =IFERROR(__xludf.DUMMYFUNCTION("""COMPUTED_VALUE"""),"PT. GUNUNG PADU PRIMAKASA") -> PT. GUNUNG PADU PRIMAKASA | C29: =IF(A29="","",COUNTIF($A$5:$J$14,A29)*45 + IFERROR(D29,0)) -> 150 | D29: 15
A30: =IFERROR(__xludf.DUMMYFUNCTION("""COMPUTED_VALUE"""),"PT. PYROTEK INDONESIA") -> PT. PYROTEK INDONESIA | C30: =IF(A30="","",COUNTIF($A$5:$J$14,A30)*45 + IFERROR(D30,0)) -> 150 | D30: 15
A31: =IFERROR(__xludf.DUMMYFUNCTION("""COMPUTED_VALUE"""),"PT. ABADI KIMIA INTERNUSA") -> PT. ABADI KIMIA INTERNUSA | C31: =IF(A31="","",COUNTIF($A$5:$J$14,A31)*45 + IFERROR(D31,0)) -> 100 | D31: 10
C32: =IF(A32="","",COUNTIF($A$5:$J$14,A32)*45 + IFERROR(D32,0))
C33: =IF(A33="","",COUNTIF($A$5:$J$14,A33)*45 + IFERROR(D33,0))
C34: =IF(A34="","",COUNTIF($A$5:$J$14,A34)*45 + IFERROR(D34,0))
C35: =IF(A35="","",COUNTIF($A$5:$J$14,A35)*45 + IFERROR(D35,0))
C36: =IF(A36="","",COUNTIF($A$5:$J$14,A36)*45 + IFERROR(D36,0))
C37: =IF(A37="","",COUNTIF($A$5:$J$14,A37)*45 + IFERROR(D37,0))
C38: =IF(A38="","",COUNTIF($A$5:$J$14,A38)*45 + IFERROR(D38,0))
C39: =IF(A39="","",COUNTIF($A$5:$J$14,A39)*45 + IFERROR(D39,0))
C40: =IF(A40="","",COUNTIF($A$5:$J$14,A40)*45 + IFERROR(D40,0))
C41: =IF(A41="","",COUNTIF($A$5:$J$14,A41)*45 + IFERROR(D41,0))
C42: =IF(A42="","",COUNTIF($A$5:$J$14,A42)*45 + IFERROR(D42,0))
C43: =IF(A43="","",COUNTIF($A$5:$J$14,A43)*45 + IFERROR(D43,0))
...

Sheet Gudang F
A1: LAYOUT GUDANG F
A3: AREA | K3: 30 M
B4: PINTU 1 | D4: PINTU 2 | G4: PINTU 3 | I4: PINTU 4
A5: PT. LUXASIA INDONESIA | C5: PT. LUXASIA INDONESIA | E5: PT. LUXASIA INDONESIA | F5: PT. LUXASIA INDONESIA | H5: PT. LUXASIA INDONESIA | J5: PT. LUXASIA INDONESIA
A6: PT. LUXASIA INDONESIA | C6: PT. LUXASIA INDONESIA | E6: PT. LUXASIA INDONESIA | F6: PT. LUXASIA INDONESIA | H6: PT. LUXASIA INDONESIA | J6: PT. LUXASIA INDONESIA
A7: PT. LUXASIA INDONESIA | C7: PT. LUXASIA INDONESIA | E7: PT. LUXASIA INDONESIA | F7: PT. LUXASIA INDONESIA | H7: PT. LUXASIA INDONESIA | J7: PT. LUXASIA INDONESIA
A8: PT. LUXASIA INDONESIA | C8: PT. LUXASIA INDONESIA | E8: PT. LUXASIA INDONESIA | F8: PT. LUXASIA INDONESIA | H8: PT. LUXASIA INDONESIA | J8: PT. LUXASIA INDONESIA
A9: PT. LUXASIA INDONESIA | C9: PT. LUXASIA INDONESIA | E9: PT. LUXASIA INDONESIA | F9: PT. LUXASIA INDONESIA | H9: PT. LUXASIA INDONESIA | J9: PT. LUXASIA INDONESIA
A10: PT. LUXASIA INDONESIA | C10: PT. LUXASIA INDONESIA | E10: PT. LUXASIA INDONESIA | F10: PT. LUXASIA INDONESIA | H10: PT. LUXASIA INDONESIA | J10: PT. LUXASIA INDONESIA
A11: PT. LUXASIA INDONESIA | C11: PT. LUXASIA INDONESIA | E11: PT. LUXASIA INDONESIA | F11: PT. LUXASIA INDONESIA | H11: PT. LUXASIA INDONESIA | J11: PT. LUXASIA INDONESIA
A12: PT. LUXASIA INDONESIA | C12: PT. LUXASIA INDONESIA | E12: PT. LUXASIA INDONESIA | F12: PT. LUXASIA INDONESIA | H12: PT. LUXASIA INDONESIA | J12: PT. LUXASIA INDONESIA
A13: PT. LUXASIA INDONESIA | C13: PT. LUXASIA INDONESIA | E13: PT. LUXASIA INDONESIA | F13: PT. LUXASIA INDONESIA | H13: PT. LUXASIA INDONESIA | J13: PT. LUXASIA INDONESIA
A14: PT. LUXASIA INDONESIA | C14: PT. LUXASIA INDONESIA | E14: PT. LUXASIA INDONESIA | F14: PT. LUXASIA INDONESIA | H14: PT. LUXASIA INDONESIA | J14: PT. LUXASIA INDONESIA
B15: PINTU 1 | D15: PINTU 2 | G15: PINTU 3 | I15: PINTU 4
A16: AREA
A17: 100 M
A20: CUSTOMER | C20: SPACE m² | D20: ADDITIONAL m² | E20: JENIS BARANG | F20: INFORMASI GUDANG
A21: =IFERROR(__xludf.DUMMYFUNCTION("IFERROR( UNIQUE( FILTER( {A5:A14;C5:C14;E5:E14;F5:F14;H5:H14;J5:J14 }, {A5:A14;C5:C14;E5:E14;F5:F14;H5:H14;J5:J14}<>"""" ) ), """" )"),"PT. LUXASIA INDONESIA") -> PT. LUXASIA INDONESIA | C21: =IF(A21="","",COUNTIF($A$5:$J$14,A21)*50 + IFERROR(D23,0)) -> 3000 | F21: Space Gudang | G21: 3000
C22: =IF(A22="","",COUNTIF($A$5:$J$14,A22)*50 + IFERROR(D24,0)) | F22: Total Terpakai | G22: =SUM(C21:C1014) -> 3000 | H22: =IFERROR(__xludf.DUMMYFUNCTION("IF( SUM(C21:C1014)<=2100, SPARKLINE(SUM(C21:C1014),{""charttype"",""bar"";""max"",3000;""color1"",""#2ECC71""}), IF( SUM(C21:C1014)<=2700, SPARKLINE(SUM(C21:C1014),{""charttype"",""bar"";""max"",3000;""color1"",""#F1C40F""}), SPARKLINE(SUM(C21:C1014),{""c"&"harttype"",""bar"";""max"",3000;""color1"",""#E74C3C""}) )) "),"")
C23: =IF(A23="","",COUNTIF($A$5:$J$14,A23)*50 + IFERROR(D25,0)) | F23: Sisa Space | G23: =G21-G22 -> 0
C24: =IF(A24="","",COUNTIF($A$5:$J$14,A24)*50 + IFERROR(D26,0)) | F24: Status Gudang | G24: =IF(G23<=0,"SPACE PENUH","SPACE TERSEDIA") -> SPACE PENUH
C25: =IF(A25="","",COUNTIF($A$5:$J$14,A25)*50 + IFERROR(D27,0))
C26: =IF(A26="","",COUNTIF($A$5:$J$14,A26)*50 + IFERROR(D28,0))
C27: =IF(A27="","",COUNTIF($A$5:$J$14,A27)*50 + IFERROR(D29,0))
C28: =IF(A28="","",COUNTIF($A$5:$J$14,A28)*50 + IFERROR(D30,0))
C29: =IF(A29="","",COUNTIF($A$5:$J$14,A29)*50 + IFERROR(D31,0))
C30: =IF(A30="","",COUNTIF($A$5:$J$14,A30)*50 + IFERROR(D32,0))
C31: =IF(A31="","",COUNTIF($A$5:$J$14,A31)*50 + IFERROR(D33,0))
C32: =IF(A32="","",COUNTIF($A$5:$J$14,A32)*50 + IFERROR(D34,0))
C33: =IF(A33="","",COUNTIF($A$5:$J$14,A33)*50 + IFERROR(D35,0))
C34: =IF(A34="","",COUNTIF($A$5:$J$14,A34)*50 + IFERROR(D36,0))
C35: =IF(A35="","",COUNTIF($A$5:$J$14,A35)*50 + IFERROR(D37,0))
C36: =IF(A36="","",COUNTIF($A$5:$J$14,A36)*50 + IFERROR(D38,0))
... C40: =IF(A40="","",COUNTIF($A$5:$J$14,A40)*50 + IFERROR(D42,0))
C41: =IF(A41="","",COUNTIF($A$5:$J$10,A41)*50 + IFERROR(D41,0))
C42: =IF(A42="","",COUNTIF($A$5:$J$10,A42)*50 + IFERROR(D42,0))
C43: =IF(A43="","",COUNTIF($A$5:$J$10,A43)*50 + IFERROR(D43,0))
C44: =IF(A44="","",COUNTIF($A$5:$J$10,A44)*50 + IFERROR(D44,0))
C45: =IF(A45="","",COUNTIF($A$5:$J$10,A45)*50 + IFERROR(D45,0))
C46: =IF(A46="","",COUNTIF($A$5:$J$10,A46)*50 + IFERROR(D46,0))
...

Sheet Gudang G
A1: LAYOUT GUDANG G
A3: AREA | K3: 30 M
B4: PINTU 1 | D4: PINTU 2 | G4: PINTU 3 | I4: PINTU 4
A5: PT. PERTAMINA PETROCHEMICAL TRADING | C5: PT. PERTAMINA PETROCHEMICAL TRADING | E5: PT. ELEKTA MEDICAL SOLUTIONS | F5: PT MITRA INTEGRASI INFORMATIKA | H5: PT MITRA INTEGRASI INFORMATIKA | J5: RECORD MANAGEMENT SERVICE
A6: PT. PERTAMINA PETROCHEMICAL TRADING | C6: PT. PERTAMINA PETROCHEMICAL TRADING | E6: PT. ELEKTA MEDICAL SOLUTIONS | F6: PT MITRA INTEGRASI INFORMATIKA | H6: PT MITRA INTEGRASI INFORMATIKA | J6: RECORD MANAGEMENT SERVICE
A7: PT. PERTAMINA PETROCHEMICAL TRADING | C7: PT. PERTAMINA PETROCHEMICAL TRADING | E7: PT. PERTAMINA PETROCHEMICAL TRADING | F7: PT MITRA INTEGRASI INFORMATIKA | H7: PT MITRA INTEGRASI INFORMATIKA | J7: RECORD MANAGEMENT SERVICE
A8: PT. PERTAMINA PETROCHEMICAL TRADING | C8: PT. PERTAMINA PETROCHEMICAL TRADING | E8: PT. PERTAMINA PETROCHEMICAL TRADING | F8: PT MITRA INTEGRASI INFORMATIKA | H8: PT MITRA INTEGRASI INFORMATIKA | J8: RECORD MANAGEMENT SERVICE
A9: PT. PERTAMINA PETROCHEMICAL TRADING | C9: PT. PERTAMINA PETROCHEMICAL TRADING | E9: PT. PERTAMINA PETROCHEMICAL TRADING | F9: PT MITRA INTEGRASI INFORMATIKA | H9: PT MITRA INTEGRASI INFORMATIKA | J9: RECORD MANAGEMENT SERVICE
A10: PT. PERTAMINA PETROCHEMICAL TRADING | C10: PT. PERTAMINA PETROCHEMICAL TRADING | E10: PT. PERTAMINA PETROCHEMICAL TRADING | F10: PT MITRA INTEGRASI INFORMATIKA | H10: RECORD MANAGEMENT SERVICE | J10: RECORD MANAGEMENT SERVICE
A11: PT. PERTAMINA PETROCHEMICAL TRADING | C11: PT. PERTAMINA PETROCHEMICAL TRADING | E11: PT. PERTAMINA PETROCHEMICAL TRADING | F11: PT MITRA INTEGRASI INFORMATIKA | H11: RECORD MANAGEMENT SERVICE | J11: RECORD MANAGEMENT SERVICE
A12: PT. PERTAMINA PETROCHEMICAL TRADING | C12: PT. PERTAMINA PETROCHEMICAL TRADING | E12: PT. PERTAMINA PETROCHEMICAL TRADING | F12: PT MITRA INTEGRASI INFORMATIKA | H12: RECORD MANAGEMENT SERVICE | J12: RECORD MANAGEMENT SERVICE
A13: PT. PERTAMINA PETROCHEMICAL TRADING | C13: PT. PERTAMINA PETROCHEMICAL TRADING | E13: PT. PERTAMINA PETROCHEMICAL TRADING | F13: PT MITRA INTEGRASI INFORMATIKA | H13: RECORD MANAGEMENT SERVICE | J13: RECORD MANAGEMENT SERVICE
A14: PT. PERTAMINA PETROCHEMICAL TRADING | C14: PT. PERTAMINA PETROCHEMICAL TRADING | E14: PT. PERTAMINA PETROCHEMICAL TRADING | F14: PT MITRA INTEGRASI INFORMATIKA | H14: RECORD MANAGEMENT SERVICE | J14: RECORD MANAGEMENT SERVICE
B15: PINTU 1 | D15: PINTU 2 | G15: PINTU 3 | I15: PINTU 4
A16: AREA
A17: 100 M
A20: CUSTOMER | C20: SPACE m² | D20: ADDITIONAL m² | E20: JENIS BARANG | F20: INFORMASI GUDANG
A21: =IFERROR(__xludf.DUMMYFUNCTION("IFERROR( UNIQUE( FILTER( {A5:A14;C5:C14;E5:E14;F5:F14;H5:H14;J5:J14 }, {A5:A14;C5:C14;E5:E14;F5:F14;H5:H14;J5:J14}<>"""" ) ), """" )"),"PT. PERTAMINA PETROCHEMICAL TRADING") -> PT. PERTAMINA PETROCHEMICAL TRADING | C21: =IF(A21="","",COUNTIF($A$5:$J$14,A21)*50 + IFERROR(D23,0)) -> 1400 | F21: Space Gudang | G21: 3000
A22: =IFERROR(__xludf.DUMMYFUNCTION("""COMPUTED_VALUE"""),"PT. ELEKTA MEDICAL SOLUTIONS") -> PT. ELEKTA MEDICAL SOLUTIONS | C22: =IF(A22="","",COUNTIF($A$5:$J$14,A22)*50 + IFERROR(D24,0)) -> 100 | F22: Total Terpakai | G22: =SUM(C21:C1014) -> 3000 | H22: =IFERROR(__xludf.DUMMYFUNCTION("IF( SUM(C21:C1014)<=2100, SPARKLINE(SUM(C21:C1014),{""charttype"",""bar"";""max"",3000;""color1"",""#2ECC71""}), IF( SUM(C21:C1014)<=2700, SPARKLINE(SUM(C21:C1014),{""charttype"",""bar"";""max"",3000;""color1"",""#F1C40F""}), SPARKLINE(SUM(C21:C1014),{""c"&"harttype"",""bar"";""max"",3000;""color1"",""#E74C3C""}) )) "),"")
A23: =IFERROR(__xludf.DUMMYFUNCTION("""COMPUTED_VALUE"""),"PT MITRA INTEGRASI INFORMATIKA") -> PT MITRA INTEGRASI INFORMATIKA | C23: =IF(A23="","",COUNTIF($A$5:$J$14,A23)*50 + IFERROR(D25,0)) -> 750 | F23: Sisa Space | G23: =G21-G22 -> 0
A24: =IFERROR(__xludf.DUMMYFUNCTION("""COMPUTED_VALUE"""),"RECORD MANAGEMENT SERVICE") -> RECORD MANAGEMENT SERVICE | C24: =IF(A24="","",COUNTIF($A$5:$J$14,A24)*50 + IFERROR(D26,0)) -> 750 | F24: Status Gudang | G24: =IF(G23<=0,"SPACE PENUH","SPACE TERSEDIA") -> SPACE PENUH
C25: =IF(A25="","",COUNTIF($A$5:$J$14,A25)*50 + IFERROR(D27,0))
C26: =IF(A26="","",COUNTIF($A$5:$J$14,A26)*50 + IFERROR(D28,0))
C27: =IF(A27="","",COUNTIF($A$5:$J$14,A27)*50 + IFERROR(D29,0))
C28: =IF(A28="","",COUNTIF($A$5:$J$14,A28)*50 + IFERROR(D30,0))
C29: =IF(A29="","",COUNTIF($A$5:$J$14,A29)*50 + IFERROR(D31,0))
C30: =IF(A30="","",COUNTIF($A$5:$J$14,A30)*50 + IFERROR(D32,0))
C31: =IF(A31="","",COUNTIF($A$5:$J$14,A31)*50 + IFERROR(D33,0))
C32: =IF(A32="","",COUNTIF($A$5:$J$14,A32)*50 + IFERROR(D34,0))
C33: =IF(A33="","",COUNTIF($A$5:$J$14,A33)*50 + IFERROR(D35,0))
C34: =IF(A34="","",COUNTIF($A$5:$J$14,A34)*50 + IFERROR(D36,0))
C35: =IF(A35="","",COUNTIF($A$5:$J$14,A35)*50 + IFERROR(D37,0))
C36: =IF(A36="","",COUNTIF($A$5:$J$14,A36)*50 + IFERROR(D38,0))
... C40: =IF(A40="","",COUNTIF($A$5:$J$14,A40)*50 + IFERROR(D42,0))
C41: =IF(A41="","",COUNTIF($A$5:$J$10,A41)*50 + IFERROR(D41,0))
C42: =IF(A42="","",COUNTIF($A$5:$J$10,A42)*50 + IFERROR(D42,0))
C43: =IF(A43="","",COUNTIF($A$5:$J$10,A43)*50 + IFERROR(D43,0))
C44: =IF(A44="","",COUNTIF($A$5:$J$10,A44)*50 + IFERROR(D44,0))
C45: =IF(A45="","",COUNTIF($A$5:$J$10,A45)*50 + IFERROR(D45,0))
C46: =IF(A46="","",COUNTIF($A$5:$J$10,A46)*50 + IFERROR(D46,0))
...

Sheet Gudang H
A1: LAYOUT GUDANG H
A3: AREA | K3: 30 M
B4: PINTU 1 | D4: PINTU 2 | G4: PINTU 3 | I4: PINTU 4
A5: PT. ASDP | C5: PT. ASDP | E5: PT. ASDP | F5: PT. GLOBAL POWER | H5: PT. NUSA ANTERO RAYA | J5: PT. EMVI
A6: PT. ASDP | C6: PT. ASDP | E6: PT. ASDP | F6: PT. GLOBAL POWER | H6: PT. NUSA ANTERO RAYA | J6: PT. EMVI
A7: PT. ASDP | C7: PT. ASDP | E7: PT. ASDP | F7: PT. GLOBAL POWER | H7: PT. NUSA ANTERO RAYA | J7: PT. EMVI
A8: PT. ASDP | C8: PT. ASDP | E8: PT. ASDP | F8: PT. NUSA RAYA ENERGI | H8: PT. NUSA ANTERO RAYA | J8: PT. EMVI
A9: PT. ASDP | C9: PT. ASDP | E9: PT. ASDP | F9: PT. NUSA RAYA ENERGI | H9: PT. PERTAMINA | J9: PT. EMVI
A10: PT. ASDP | C10: PT. ASDP | E10: PT. ASDP | F10: PT. TRI BANGUN HUSADA | H10: PT. PERTAMINA | J10: PT. EMVI
A11: PT. ASDP | C11: PT. ASDP | E11: PT. ASDP | F11: PT. TRI BANGUN HUSADA | H11: PT. PERTAMINA | J11: PT. EMVI
A12: PT. ASDP | C12: PT. ASDP | E12: PT. ASDP | F12: PT. NEOSYS | H12: PT. PERTAMINA | J12: PT. PERTAMINA
A13: PT. ASDP | C13: PT. ASDP | E13: PT. ASDP | F13: PT. NEOSYS | H13: PT. PERTAMINA | J13: PT. PERTAMINA
A14: PT. ASDP | C14: PT. ASDP | E14: PT. ASDP | F14: PT.EMVI | H14: PT. PERTAMINA | J14: PT. PERTAMINA
B15: PINTU 1 | D15: PINTU 2 | G15: PINTU 3 | I15: PINTU 4
A16: AREA
A17: 100 M
A20: CUSTOMER | D20: ADDITIONAL m² | E20: JENIS BARANG | F20: INFORMASI GUDANG
A21: =IFERROR(__xludf.DUMMYFUNCTION("IFERROR( UNIQUE( FILTER( {A5:A14;C5:C14;E5:E14;F5:F14;H5:H14;J5:J14 }, {A5:A14;C5:C14;E5:E14;F5:F14;H5:H14;J5:J14}<>"""" ) ), """" )"),"PT. ASDP ") -> PT. ASDP | C21: =IF(A21="","",COUNTIF($A$5:$J$14,A21)*50 + IFERROR(D23,0)) -> 1500 | F21: Space Gudang | G21: 3000
A22: =IFERROR(__xludf.DUMMYFUNCTION("""COMPUTED_VALUE"""),"PT. GLOBAL POWER") -> PT. GLOBAL POWER | C22: =IF(A22="","",COUNTIF($A$5:$J$14,A22)*50 + IFERROR(D24,0)) -> 150 | F22: Total Terpakai | G22: =SUM(C21:C1014) -> 3000 | H22: =IFERROR(__xludf.DUMMYFUNCTION("IF( SUM(C21:C1014)<=2100, SPARKLINE(SUM(C21:C1014),{""charttype"",""bar"";""max"",3000;""color1"",""#2ECC71""}), IF( SUM(C21:C1014)<=2700, SPARKLINE(SUM(C21:C1014),{""charttype"",""bar"";""max"",3000;""color1"",""#F1C40F""}), SPARKLINE(SUM(C21:C1014),{""c"&"harttype"",""bar"";""max"",3000;""color1"",""#E74C3C""}) )) "),"")
A23: =IFERROR(__xludf.DUMMYFUNCTION("""COMPUTED_VALUE"""),"PT. NUSA RAYA ENERGI") -> PT. NUSA RAYA ENERGI | C23: =IF(A23="","",COUNTIF($A$5:$J$14,A23)*50 + IFERROR(D25,0)) -> 100 | F23: Sisa Space | G23: =G21-G22 -> 0
A24: =IFERROR(__xludf.DUMMYFUNCTION("""COMPUTED_VALUE"""),"PT. TRI BANGUN HUSADA") -> PT. TRI BANGUN HUSADA | C24: =IF(A24="","",COUNTIF($A$5:$J$14,A24)*50 + IFERROR(D26,0)) -> 100 | F24: Status Gudang | G24: =IF(G23<=0,"SPACE PENUH","SPACE TERSEDIA") -> SPACE PENUH
A25: =IFERROR(__xludf.DUMMYFUNCTION("""COMPUTED_VALUE"""),"PT. NEOSYS") -> PT. NEOSYS | C25: =IF(A25="","",COUNTIF($A$5:$J$14,A25)*50 + IFERROR(D27,0)) -> 100
A26: =IFERROR(__xludf.DUMMYFUNCTION("""COMPUTED_VALUE"""),"PT.EMVI") -> PT.EMVI | C26: =IF(A26="","",COUNTIF($A$5:$J$14,A26)*50 + IFERROR(D28,0)) -> 50
A27: =IFERROR(__xludf.DUMMYFUNCTION("""COMPUTED_VALUE"""),"PT. NUSA ANTERO RAYA ") -> PT. NUSA ANTERO RAYA | C27: 200
A28: =IFERROR(__xludf.DUMMYFUNCTION("""COMPUTED_VALUE"""),"PT. PERTAMINA") -> PT. PERTAMINA | C28: =IF(A28="","",COUNTIF($A$5:$J$14,A28)*50 + IFERROR(D30,0)) -> 450
A29: =IFERROR(__xludf.DUMMYFUNCTION("""COMPUTED_VALUE"""),"PT. EMVI ") -> PT. EMVI | C29: =IF(A29="","",COUNTIF($A$5:$J$14,A29)*50 + IFERROR(D31,0)) -> 350 | D29: 30
C30: =IF(A30="","",COUNTIF($A$5:$J$14,A30)*50 + IFERROR(D32,0))
C31: =IF(A31="","",COUNTIF($A$5:$J$14,A31)*50 + IFERROR(D33,0))
C32: =IF(A32="","",COUNTIF($A$5:$J$14,A32)*50 + IFERROR(D34,0))
C33: =IF(A33="","",COUNTIF($A$5:$J$14,A33)*50 + IFERROR(D35,0))
C34: =IF(A34="","",COUNTIF($A$5:$J$14,A34)*50 + IFERROR(D36,0))
C35: =IF(A35="","",COUNTIF($A$5:$J$14,A35)*50 + IFERROR(D37,0))
C36: =IF(A36="","",COUNTIF($A$5:$J$14,A36)*50 + IFERROR(D38,0))
C37: =IF(A37="","",COUNTIF($A$5:$J$14,A37)*50 + IFERROR(D39,0))
C38: =IF(A38="","",COUNTIF($A$5:$J$14,A38)*50 + IFERROR(D40,0))
C39: =IF(A39="","",COUNTIF($A$5:$J$14,A39)*50 + IFERROR(D41,0))
C40: =IF(A40="","",COUNTIF($A$5:$J$14,A40)*50 + IFERROR(D42,0))
C41: =IF(A41="","",COUNTIF($A$5:$J$10,A41)*50 + IFERROR(D41,0))
C42: =IF(A42="","",COUNTIF($A$5:$J$10,A42)*50 + IFERROR(D42,0))
C43: =IF(A43="","",COUNTIF($A$5:$J$10,A43)*50 + IFERROR(D43,0))
...

Sheet Gudang I-1
A1: LAYOUT GUDANG I-1
A3: AREA
B4: PINTU 1 | D4: PINTU 2 | G4: PINTU 3 | I4: PINTU 4 | K4: 30 M
A5: PT. PERKEBUNAN NUSANTARA | C5: PT. PERKEBUNAN NUSANTARA | E5: PT. PERKEBUNAN NUSANTARA | F5: PT. PERKEBUNAN NUSANTARA | H5: PT. PERKEBUNAN NUSANTARA | J5: PT. PERKEBUNAN NUSANTARA
A6: PT. PERKEBUNAN NUSANTARA | C6: PT. PERKEBUNAN NUSANTARA | E6: PT. PERKEBUNAN NUSANTARA | F6: PT. PERKEBUNAN NUSANTARA | H6: PT. PERKEBUNAN NUSANTARA | J6: PT. PERKEBUNAN NUSANTARA
A7: PT. PERKEBUNAN NUSANTARA | C7: PT. PERKEBUNAN NUSANTARA | E7: PT. PERKEBUNAN NUSANTARA | F7: PT. PERKEBUNAN NUSANTARA | H7: PT. PERKEBUNAN NUSANTARA | J7: PT. PERKEBUNAN NUSANTARA
A8: PT. PERKEBUNAN NUSANTARA | C8: PT. PERKEBUNAN NUSANTARA | E8: PT. PERKEBUNAN NUSANTARA | F8: PT. PERKEBUNAN NUSANTARA | H8: PT. PERKEBUNAN NUSANTARA | J8: PT. PERKEBUNAN NUSANTARA
A9: PT. PERKEBUNAN NUSANTARA | C9: PT. PERKEBUNAN NUSANTARA | E9: PT. PERKEBUNAN NUSANTARA | F9: PT. PERKEBUNAN NUSANTARA | H9: PT. PERKEBUNAN NUSANTARA | J9: PT. PERKEBUNAN NUSANTARA
A10: PT. PERKEBUNAN NUSANTARA | C10: PT. PERKEBUNAN NUSANTARA | E10: PT. PERKEBUNAN NUSANTARA | F10: PT. PERKEBUNAN NUSANTARA | H10: PT. PERKEBUNAN NUSANTARA | J10: PT. PERKEBUNAN NUSANTARA
A11: PT. PERKEBUNAN NUSANTARA | C11: PT. PERKEBUNAN NUSANTARA | E11: PT. PERKEBUNAN NUSANTARA | F11: PT. PERKEBUNAN NUSANTARA | H11: PT. PERKEBUNAN NUSANTARA | J11: PT. PERKEBUNAN NUSANTARA
A12: PT. PERKEBUNAN NUSANTARA | C12: PT. PERKEBUNAN NUSANTARA | E12: PT. PERKEBUNAN NUSANTARA | F12: PT. PERKEBUNAN NUSANTARA | H12: PT. PERKEBUNAN NUSANTARA | J12: PT. PERKEBUNAN NUSANTARA
A13: PT. TJAN KEE DJANG | C13: PT. PERKEBUNAN NUSANTARA | E13: PT. PERKEBUNAN NUSANTARA | F13: PT. PERKEBUNAN NUSANTARA | H13: PT. PERKEBUNAN NUSANTARA | J13: PT. PERKEBUNAN NUSANTARA
A14: PT. TJAN KEE DJANG | C14: PT. PERKEBUNAN NUSANTARA | E14: PT. PERKEBUNAN NUSANTARA | F14: PT. PERKEBUNAN NUSANTARA | H14: PT. PERKEBUNAN NUSANTARA | J14: PT. PERKEBUNAN NUSANTARA
B15: PINTU 1 | D15: PINTU 2 | G15: PINTU 3 | I15: PINTU 4
A16: AREA
A17: 96 M
A20: CUSTOMER | C20: SPACE m² | D20: ADDITIONAL m² | E20: JENIS BARANG | F20: INFORMASI GUDANG
A21: =IFERROR(__xludf.DUMMYFUNCTION("IFERROR( UNIQUE( FILTER( {A5:A14;C5:C14;E5:E14;F5:F14;H5:H14;J5:J14 }, {A5:A14;C5:C14;E5:E14;F5:F14;H5:H14;J5:J14}<>"""" ) ), """" )"),"PT. PERKEBUNAN NUSANTARA") -> PT. PERKEBUNAN NUSANTARA | C21: =IF(A21="","",COUNTIF($A$5:$J$14,A21)*50 + IFERROR(D23,0)) -> 2900 | E21: Teh Kemasan | F21: Space Gudang | G21: 3000
A22: =IFERROR(__xludf.DUMMYFUNCTION("""COMPUTED_VALUE"""),"PT. TJAN KEE DJANG") -> PT. TJAN KEE DJANG | C22: =IF(A22="","",COUNTIF($A$5:$J$14,A22)*50 + IFERROR(D24,0)) -> 100 | E22: Elektronik | F22: Total Terpakai | G22: =SUM(C21:C1014) -> 3000 | H22: =IFERROR(__xludf.DUMMYFUNCTION("IF( SUM(C21:C1014)<=2100, SPARKLINE(SUM(C21:C1014),{""charttype"",""bar"";""max"",3000;""color1"",""#2ECC71""}), IF( SUM(C21:C1014)<=2700, SPARKLINE(SUM(C21:C1014),{""charttype"",""bar"";""max"",3000;""color1"",""#F1C40F""}), SPARKLINE(SUM(C21:C1014),{""c"&"harttype"",""bar"";""max"",3000;""color1"",""#E74C3C""}) )) "),"")
C23: =IF(A23="","",COUNTIF($A$5:$J$14,A23)*50 + IFERROR(D25,0)) | F23: Sisa Space | G23: =G21-G22 -> 0
C24: =IF(A24="","",COUNTIF($A$5:$J$14,A24)*50 + IFERROR(D26,0)) | F24: Status Gudang | G24: =IF(G23<=0,"SPACE PENUH","SPACE TERSEDIA") -> SPACE PENUH
C25: =IF(A25="","",COUNTIF($A$5:$J$14,A25)*50 + IFERROR(D27,0))
C26: =IF(A26="","",COUNTIF($A$5:$J$14,A26)*50 + IFERROR(D28,0))
C27: =IF(A27="","",COUNTIF($A$5:$J$14,A27)*50 + IFERROR(D29,0))
C28: =IF(A28="","",COUNTIF($A$5:$J$14,A28)*50 + IFERROR(D30,0))
C29: =IF(A29="","",COUNTIF($A$5:$J$14,A29)*50 + IFERROR(D31,0))
C30: =IF(A30="","",COUNTIF($A$5:$J$14,A30)*50 + IFERROR(D32,0))
C31: =IF(A31="","",COUNTIF($A$5:$J$14,A31)*50 + IFERROR(D33,0))
C32: =IF(A32="","",COUNTIF($A$5:$J$14,A32)*50 + IFERROR(D34,0))
C33: =IF(A33="","",COUNTIF($A$5:$J$14,A33)*50 + IFERROR(D35,0))
C34: =IF(A34="","",COUNTIF($A$5:$J$14,A34)*50 + IFERROR(D36,0))
C35: =IF(A35="","",COUNTIF($A$5:$J$14,A35)*50 + IFERROR(D37,0))
C36: =IF(A36="","",COUNTIF($A$5:$J$14,A36)*50 + IFERROR(D38,0))
... C40: =IF(A40="","",COUNTIF($A$5:$J$14,A40)*50 + IFERROR(D42,0))
C41: =IF(A41="","",COUNTIF($A$5:$J$10,A41)*50 + IFERROR(D41,0))
C42: =IF(A42="","",COUNTIF($A$5:$J$10,A42)*50 + IFERROR(D42,0))
C43: =IF(A43="","",COUNTIF($A$5:$J$10,A43)*50 + IFERROR(D43,0))
C44: =IF(A44="","",COUNTIF($A$5:$J$10,A44)*50 + IFERROR(D44,0))
C45: =IF(A45="","",COUNTIF($A$5:$J$10,A45)*50 + IFERROR(D45,0))
C46: =IF(A46="","",COUNTIF($A$5:$J$10,A46)*50 + IFERROR(D46,0))
...

Sheet Gudang I-2
A1: LAYOUT GUDANG I-2
A3: AREA
B4: PINTU 1 | D4: PINTU 2 | G4: PINTU 3 | I4: PINTU 4 | K4: 30 M
A5: PT. GLOBAL POWER | C5: PT. PERTAMINA PETROCHEMICAL TRADING | E5: Barang Sitaan Polisi | F5: PT. PERTAMINA PETROCHEMICAL TRADING | H5: PT. PERTAMINA PETROCHEMICAL TRADING | J5: PT. PERTAMINA PETROCHEMICAL TRADING
A6: PT. GLOBAL POWER | C6: PT. PERTAMINA PETROCHEMICAL TRADING | E6: PT. PERTAMINA PETROCHEMICAL TRADING | F6: PT. PERTAMINA PETROCHEMICAL TRADING | H6: PT. PERTAMINA PETROCHEMICAL TRADING | J6: PT. PERTAMINA PETROCHEMICAL TRADING
A7: PT. GLOBAL POWER | C7: PT. KOMDIGI | E7: PT. PERTAMINA PETROCHEMICAL TRADING | F7: PT. PERTAMINA PETROCHEMICAL TRADING | H7: PT. PERKEBUNAN NUSANTARA | J7: PT. PERTAMINA PETROCHEMICAL TRADING
A8: PT. KOMDIGI | C8: PT. KOMDIGI | E8: PT. PERTAMINA PETROCHEMICAL TRADING | F8: PT. PERTAMINA PETROCHEMICAL TRADING | H8: PT. PERKEBUNAN NUSANTARA | J8: PT. PERTAMINA PETROCHEMICAL TRADING
A9: PT. KOMDIGI | C9: PT. KOMDIGI | E9: PT. PERTAMINA PETROCHEMICAL TRADING | F9: PT. PERTAMINA PETROCHEMICAL TRADING | H9: PT. PERKEBUNAN NUSANTARA | J9: PT. PERKEBUNAN NUSANTARA
A10: PT. KOMDIGI | C10: PT. KOMDIGI | E10: PT. PERTAMINA PETROCHEMICAL TRADING | F10: PT. PERTAMINA PETROCHEMICAL TRADING | H10: PT. PERKEBUNAN NUSANTARA | J10: PT. PERKEBUNAN NUSANTARA
A11: PT. ASDP | C11: PT. KOMDIGI | E11: PT. PERTAMINA PETROCHEMICAL TRADING | F11: PT. PERTAMINA PETROCHEMICAL TRADING | H11: PT. PERKEBUNAN NUSANTARA | J11: PT. PERKEBUNAN NUSANTARA
A12: PT. ASDP | C12: PT. KOMDIGI | E12: PT. PERTAMINA PETROCHEMICAL TRADING | F12: PT. PERTAMINA PETROCHEMICAL TRADING | H12: PT. PERKEBUNAN NUSANTARA | J12: PT. PERKEBUNAN NUSANTARA
A13: PT. PERTAMINA PETROCHEMICAL TRADING | C13: PT. KOMDIGI | E13: PT. PERTAMINA PETROCHEMICAL TRADING | F13: WARUNG PANGAN ( PPI ) | H13: WARUNG PANGAN ( PPI ) | J13: PT. PERKEBUNAN NUSANTARA
A14: EX COVID 19 | C14: Barang Sitaan Polisi | E14: PT. PERTAMINA PETROCHEMICAL TRADING | F14: WARUNG PANGAN ( PPI ) | H14: WARUNG PANGAN ( PPI ) | J14: PT. PERKEBUNAN NUSANTARA
B15: PINTU 1 | D15: PINTU 2 | G15: PINTU 3 | I15: PINTU 4
A16: AREA
A17: 96 M
A20: CUSTOMER | C20: SPACE m² | D20: ADDITIONAL m² | E20: JENIS BARANG | F20: INFORMASI GUDANG
A21: =IFERROR(__xludf.DUMMYFUNCTION("IFERROR( UNIQUE( FILTER( {A5:A14;C5:C14;E5:E14;F5:F14;H5:H14;J5:J14 }, {A5:A14;C5:C14;E5:E14;F5:F14;H5:H14;J5:J14}<>"""" ) ), """" )"),"PT. GLOBAL POWER") -> PT. GLOBAL POWER | C21: =IF(A21="","",COUNTIF($A$5:$J$14,A21)*50 + IFERROR(D23,0)) -> 150 | E21: Baterai | F21: Space Gudang | G21: 3000
A22: =IFERROR(__xludf.DUMMYFUNCTION("""COMPUTED_VALUE"""),"PT. KOMDIGI") -> PT. KOMDIGI | C22: =IF(A22="","",COUNTIF($A$5:$J$14,A22)*50 + IFERROR(D24,0)) -> 500 | E22: Aset Kantor | F22: Total Terpakai | G22: =SUM(C21:C1014) -> 3000 | H22: =IFERROR(__xludf.DUMMYFUNCTION("IF( SUM(C21:C1014)<=2100, SPARKLINE(SUM(C21:C1014),{""charttype"",""bar"";""max"",3000;""color1"",""#2ECC71""}), IF( SUM(C21:C1014)<=2700, SPARKLINE(SUM(C21:C1014),{""charttype"",""bar"";""max"",3000;""color1"",""#F1C40F""}), SPARKLINE(SUM(C21:C1014),{""c"&"harttype"",""bar"";""max"",3000;""color1"",""#E74C3C""}) )) "),"")
A23: =IFERROR(__xludf.DUMMYFUNCTION("""COMPUTED_VALUE"""),"PT. ASDP") -> PT. ASDP | C23: =IF(A23="","",COUNTIF($A$5:$J$14,A23)*50 + IFERROR(D25,0)) -> 100 | E23: Aseso mesin kapal | F23: Sisa Space | G23: =G21-G22 -> 0
A24: =IFERROR(__xludf.DUMMYFUNCTION("""COMPUTED_VALUE"""),"PT. PERTAMINA PETROCHEMICAL TRADING") -> PT. PERTAMINA PETROCHEMICAL TRADING | C24: =IF(A24="","",COUNTIF($A$5:$J$14,A24)*50 + IFERROR(D26,0)) -> 1300 | E24: Biji Plastik | F24: Status Gudang | G24: =IF(G23<=0,"SPACE PENUH","SPACE TERSEDIA") -> SPACE PENUH
A25: =IFERROR(__xludf.DUMMYFUNCTION("""COMPUTED_VALUE"""),"EX COVID 19") -> EX COVID 19 | C25: =IF(A25="","",COUNTIF($A$5:$J$14,A25)*50 + IFERROR(D27,0)) -> 50 | E25: Peralatan Medis
A26: =IFERROR(__xludf.DUMMYFUNCTION("""COMPUTED_VALUE"""),"Barang Sitaan Polisi") -> Barang Sitaan Polisi | C26: =IF(A26="","",COUNTIF($A$5:$J$14,A26)*50 + IFERROR(D28,0)) -> 100 | E26: Hand Sanitaizer
A27: =IFERROR(__xludf.DUMMYFUNCTION("""COMPUTED_VALUE"""),"WARUNG PANGAN ( PPI )") -> WARUNG PANGAN ( PPI ) | C27: =IF(A27="","",COUNTIF($A$5:$J$14,A27)*50 + IFERROR(D29,0)) -> 200 | E27: Peralatan Bekas
A28: =IFERROR(__xludf.DUMMYFUNCTION("""COMPUTED_VALUE"""),"PT. PERKEBUNAN NUSANTARA ") -> PT. PERKEBUNAN NUSANTARA | C28: =IF(A28="","",COUNTIF($A$5:$J$14,A28)*50 + IFERROR(D30,0)) -> 600 | E28: Teh Kemasan
C29: =IF(A29="","",COUNTIF($A$5:$J$14,A29)*50 + IFERROR(D31,0))
C30: =IF(A30="","",COUNTIF($A$5:$J$14,A30)*50 + IFERROR(D32,0))
C31: =IF(A31="","",COUNTIF($A$5:$J$14,A31)*50 + IFERROR(D33,0))
C32: =IF(A32="","",COUNTIF($A$5:$J$14,A32)*50 + IFERROR(D34,0))
C33: =IF(A33="","",COUNTIF($A$5:$J$14,A33)*50 + IFERROR(D35,0))
C34: =IF(A34="","",COUNTIF($A$5:$J$14,A34)*50 + IFERROR(D36,0))
C35: =IF(A35="","",COUNTIF($A$5:$J$14,A35)*50 + IFERROR(D37,0))
C36: =IF(A36="","",COUNTIF($A$5:$J$14,A36)*50 + IFERROR(D38,0))
C37: =IF(A37="","",COUNTIF($A$5:$J$14,A37)*50 + IFERROR(D39,0))
C38: =IF(A38="","",COUNTIF($A$5:$J$14,A38)*50 + IFERROR(D40,0))
C39: =IF(A39="","",COUNTIF($A$5:$J$14,A39)*50 + IFERROR(D41,0))
C40: =IF(A40="","",COUNTIF($A$5:$J$14,A40)*50 + IFERROR(D42,0))
C41: =IF(A41="","",COUNTIF($A$5:$J$10,A41)*50 + IFERROR(D41,0))
C42: =IF(A42="","",COUNTIF($A$5:$J$10,A42)*50 + IFERROR(D42,0))
C43: =IF(A43="","",COUNTIF($A$5:$J$10,A43)*50 + IFERROR(D43,0))
...

Sheet Gudang J-1
A1: LAYOUT GUDANG J-1
A3: AREA | I3: 30 M
A5: PT. SARINAH | C5: PT. SARINAH | D5: PT. METRO POLITAN MART | E5: PT. METRO POLITAN MART | F5: PT. AROMA PRIMA | H5: PT. MARTON
A6: PT. SARINAH | C6: PT. SARINAH | D6: PT. METRO POLITAN MART | E6: PT. METRO POLITAN MART | F6: PT. AROMA PRIMA | H6: PT. MARTON
A7: PT. SARINAH | C7: PT. SARINAH | D7: PT. METRO POLITAN MART | E7: PT. METRO POLITAN MART | F7: PT. AROMA PRIMA | H7: PT. MARTON
A8: PT. SARINAH | C8: PT. SARINAH | D8: PT. METRO POLITAN MART | E8: PT. DINI RAYA | F8: PT. GELPI | H8: PT. MARTON
A9: PT. SARINAH | C9: PT. SARINAH | D9: PT. METRO POLITAN MART | E9: PT. DINI RAYA | F9: PT. GELPI | H9: PT. MARTON
A10: PT. SARINAH | C10: PT. SARINAH | D10: PT. METRO POLITAN MART | E10: PT. DINI RAYA | F10: PT. GELPI | H10: PT. MARTON
A11: PT. SARINAH | C11: PT. SARINAH | D11: PT. METRO POLITAN MART | E11: PT. DINI RAYA | F11: PT. GELPI | H11: PT. MARTON
A12: PT. SARINAH | C12: PT. SARINAH | D12: PT. METRO POLITAN MART | E12: PT. DINI RAYA | F12: PT, GUNUNG PADU | H12: PT. MARTON
A13: PT. SARINAH | C13: PT. SARINAH | D13: PT. METRO POLITAN MART | E13: PT. AROMA PRIMA | F13: PT. GOLBAL MRS | H13: PT. MARTON
A14: PT. SARINAH | C14: PT. SARINAH | D14: PT. METRO POLITAN MART | E14: PT. AROMA PRIMA | F14: PT. KIANG DENTAL | H14: PT. MARTON
B15: PINTU 1 | G15: PINTU 2
A16: AREA
A17: 50 M
A20: CUSTOMER | C20: SPACE m² | D20: ADDITIONAL m² | E20: JENIS BARANG | F20: INFORMASI GUDANG
A21: =IFERROR(__xludf.DUMMYFUNCTION("IFERROR( UNIQUE( FILTER( {A5:A14;C5:C14;D5:D14;E7:E14;F5:F14;H5:H14 }, {A5:A14;C5:C14;D5:D14;E7:E14;F5:F14;H5:H14}<>"""" ) ), """" )"),"PT. SARINAH") -> PT. SARINAH | C21: =IF(A21="","",COUNTIF($A$5:$H$14,A21)*20 + IFERROR(D21,0)) -> 400 | F21: Space Gudang | G21: 1500
A22: =IFERROR(__xludf.DUMMYFUNCTION("""COMPUTED_VALUE"""),"PT. METRO POLITAN MART") -> PT. METRO POLITAN MART | C22: =IF(A22="","",COUNTIF($A$5:$H$14,A22)*20 + IFERROR(D22,0)) -> 260 | F22: Total Terpakai | G22: =SUM(C21:C1014) -> 1460 | H22: =IFERROR(__xludf.DUMMYFUNCTION("IF( SUM(C21:C1014)<=2100, SPARKLINE(SUM(C21:C1014),{""charttype"",""bar"";""max"",3000;""color1"",""#2ECC71""}), IF( SUM(C21:C1014)<=2700, SPARKLINE(SUM(C21:C1014),{""charttype"",""bar"";""max"",3000;""color1"",""#F1C40F""}), SPARKLINE(SUM(C21:C1014),{""c"&"harttype"",""bar"";""max"",3000;""color1"",""#E74C3C""}) )) "),"")
A23: =IFERROR(__xludf.DUMMYFUNCTION("""COMPUTED_VALUE"""),"PT. DINI RAYA") -> PT. DINI RAYA | C23: =IF(A23="","",COUNTIF($A$5:$H$14,A23)*20 + IFERROR(D23,0)) -> 100 | F23: Sisa Space | G23: =G21-G22 -> 40
A24: =IFERROR(__xludf.DUMMYFUNCTION("""COMPUTED_VALUE"""),"PT. AROMA PRIMA") -> PT. AROMA PRIMA | C24: =IF(A24="","",COUNTIF($A$5:$H$14,A24)*20 + IFERROR(D24,0)) -> 100 | F24: Status Gudang | G24: =IF(G23<=0,"SPACE PENUH","SPACE TERSEDIA") -> SPACE TERSEDIA
A25: =IFERROR(__xludf.DUMMYFUNCTION("""COMPUTED_VALUE"""),"PT. GELPI") -> PT. GELPI | C25: =IF(A25="","",COUNTIF($A$5:$H$14,A25)*20 + IFERROR(D25,0)) -> 90 | D25: 10
A26: =IFERROR(__xludf.DUMMYFUNCTION("""COMPUTED_VALUE"""),"PT, GUNUNG PADU") -> PT, GUNUNG PADU | C26: =IF(A26="","",COUNTIF($A$5:$H$14,A26)*20 + IFERROR(D26,0)) -> 50 | D26: 30
A27: =IFERROR(__xludf.DUMMYFUNCTION("""COMPUTED_VALUE"""),"PT. GOLBAL MRS") -> PT. GOLBAL MRS | C27: =IF(A27="","",COUNTIF($A$5:$H$14,A27)*20 + IFERROR(D27,0)) -> 50 | D27: 30
A28: =IFERROR(__xludf.DUMMYFUNCTION("""COMPUTED_VALUE"""),"PT. KIANG DENTAL") -> PT. KIANG DENTAL | C28: =IF(A28="","",COUNTIF($A$5:$H$14,A28)*20 + IFERROR(D28,0)) -> 50 | D28: 30
A29: =IFERROR(__xludf.DUMMYFUNCTION("""COMPUTED_VALUE"""),"PT. MARTON ") -> PT. MARTON | C29: =IF(A29="","",COUNTIF($A$5:$H$14,A29)*20 + IFERROR(D29,0)) -> 360 | D29: 160
C30: =IF(A30="","",COUNTIF($A$5:$H$14,A30)*20 + IFERROR(D30,0))
C31: =IF(A31="","",COUNTIF($A$5:$H$14,A31)*20 + IFERROR(D31,0))
C32: =IF(A32="","",COUNTIF($A$5:$H$14,A32)*20 + IFERROR(D32,0))
C33: =IF(A33="","",COUNTIF($A$5:$H$14,A33)*20 + IFERROR(D33,0))
C34: =IF(A34="","",COUNTIF($A$5:$H$14,A34)*20 + IFERROR(D34,0))
C35: =IF(A35="","",COUNTIF($A$5:$H$14,A35)*20 + IFERROR(D35,0))
C36: =IF(A36="","",COUNTIF($A$5:$H$14,A36)*20 + IFERROR(D36,0))
C37: =IF(A37="","",COUNTIF($A$5:$H$14,A37)*20 + IFERROR(D37,0))
C38: =IF(A38="","",COUNTIF($A$5:$H$14,A38)*20 + IFERROR(D38,0))
C39: =IF(A39="","",COUNTIF($A$5:$H$14,A39)*20 + IFERROR(D39,0))
C40: =IF(A40="","",COUNTIF($A$5:$H$14,A40)*20 + IFERROR(D40,0))
C41: =IF(A41="","",COUNTIF($A$5:$H$14,A41)*20 + IFERROR(D41,0))
... C1014: =IF(A1014="","",COUNTIF($A$5:$H$14,A1014)*20 + IFERROR(D1014,0))

Sheet Gudang J-2
A1: LAYOUT GUDANG J-2
A3: AREA | I3: 30 M
A5: PT. FRESH FACTORY (SEGAR ) | C5: PT. HOSHIZAKI INDONESIA | D5: PT. HOSHIZAKI INDONESIA | E5: PT. HOSHIZAKI INDONESIA | F5: PT. HOSHIZAKI INDONESIA | H5: PT. HOSHIZAKI INDONESIA
A6: PT. FRESH FACTORY (SEGAR ) | C6: PT. HOSHIZAKI INDONESIA | D6: PT. HOSHIZAKI INDONESIA | E6: PT. HOSHIZAKI INDONESIA | F6: PT. HOSHIZAKI INDONESIA | H6: PT. HOSHIZAKI INDONESIA
A7: PT. FRESH FACTORY (SEGAR ) | D7: PT. HOSHIZAKI INDONESIA | E7: PT. HOSHIZAKI INDONESIA | F7: PT. HOSHIZAKI INDONESIA | H7: PT. HOSHIZAKI INDONESIA
A8: PT. FRESH FACTORY (SEGAR ) | D8: PT. HOSHIZAKI INDONESIA | E8: PT. HOSHIZAKI INDONESIA | F8: PT. HOSHIZAKI INDONESIA | H8: PT. HOSHIZAKI INDONESIA
A9: PT. MULIA INSPIRA LOGISTIK | D9: PT. HOSHIZAKI INDONESIA | E9: PT. HOSHIZAKI INDONESIA | F9: PT. HOSHIZAKI INDONESIA | H9: PT. HOSHIZAKI INDONESIA
A10: PT. MULIA INSPIRA LOGISTIK | D10: PT. HOSHIZAKI INDONESIA | E10: PT. HOSHIZAKI INDONESIA | F10: PT. HOSHIZAKI INDONESIA | H10: PT. HOSHIZAKI INDONESIA
A11: PT. MULIA INSPIRA LOGISTIK | D11: PT. HOSHIZAKI INDONESIA | E11: PT. HOSHIZAKI INDONESIA | F11: PT. HOSHIZAKI INDONESIA | H11: PT. HOSHIZAKI INDONESIA
A12: PT. MULIA INSPIRA LOGISTIK | D12: PT. HOSHIZAKI INDONESIA | E12: PT. HOSHIZAKI INDONESIA | F12: PT. HOSHIZAKI INDONESIA | H12: PT. HOSHIZAKI INDONESIA
A13: PT. MULIA INSPIRA LOGISTIK | D13: PT. HOSHIZAKI INDONESIA | E13: PT. HOSHIZAKI INDONESIA | F13: PT. HOSHIZAKI INDONESIA | H13: PT. HOSHIZAKI INDONESIA
A14: PT. MULIA INSPIRA LOGISTIK | D14: PT. HOSHIZAKI INDONESIA | E14: PT. HOSHIZAKI INDONESIA | F14: PT. HOSHIZAKI INDONESIA | H14: PT. HOSHIZAKI INDONESIA
B15: PINTU 1 | G15: PINTU 2
A16: AREA
A17: 50 M
A20: CUSTOMER | C20: SPACE m² | D20: ADDITIONAL m² | E20: JENIS BARANG | F20: INFORMASI GUDANG
A21: =IFERROR(__xludf.DUMMYFUNCTION("IFERROR( UNIQUE( FILTER( {A5:A14;C5:C14;D5:D14;E5:E14;F5:F14;H5:H14 }, {A5:A14;C5:C14;D5:D14;E5:E14;F5:F14;H5:H14}<>"""" ) ), """" )"),"PT. FRESH FACTORY (SEGAR )") -> PT. FRESH FACTORY (SEGAR ) | C21: =IF(A21="","",COUNTIF($A$5:$H$14,A21)*25 + IFERROR(D21,0)) -> 100 | F21: Space Gudang | G21: 1500
A22: =IFERROR(__xludf.DUMMYFUNCTION("""COMPUTED_VALUE"""),"PT. MULIA INSPIRA LOGISTIK") -> PT. MULIA INSPIRA LOGISTIK | C22: =IF(A22="","",COUNTIF($A$5:$H$14,A22)*25 + IFERROR(D22,0)) -> 150 | F22: Total Terpakai | G22: =SUM(C21:C1014) -> 1320 | H22: =IFERROR(__xludf.DUMMYFUNCTION("IF( SUM(C21:C1014)<=800, SPARKLINE(SUM(C21:C1014),{""charttype"",""bar"";""max"",1500;""color1"",""#2ECC71""}), IF( SUM(C21:C1014)<=1200, SPARKLINE(SUM(C21:C1014),{""charttype"",""bar"";""max"",1500;""color1"",""#F1C40F""}), SPARKLINE(SUM(C21:C1014),{""ch"&"arttype"",""bar"";""max"",1500;""color1"",""#E74C3C""}) )) "),"")
A23: =IFERROR(__xludf.DUMMYFUNCTION("""COMPUTED_VALUE"""),"PT. HOSHIZAKI INDONESIA") -> PT. HOSHIZAKI INDONESIA | C23: =IF(A23="","",COUNTIF($A$5:$H$14,A23)*25 + IFERROR(D23,0)) -> 1070 | D23: 20 | F23: Sisa Space | G23: =G21-G22 -> 180
C24: =IF(A24="","",COUNTIF($A$5:$H$14,A24)*25 + IFERROR(D24,0)) | F24: Status Gudang | G24: =IF(G23<=0,"SPACE PENUH","SPACE TERSEDIA") -> SPACE TERSEDIA
C25: =IF(A25="","",COUNTIF($A$5:$H$14,A25)*25 + IFERROR(D25,0))
C26: =IF(A26="","",COUNTIF($A$5:$H$14,A26)*25 + IFERROR(D26,0))
C27: =IF(A27="","",COUNTIF($A$5:$H$14,A27)*25 + IFERROR(D27,0))
C28: =IF(A28="","",COUNTIF($A$5:$H$14,A28)*25 + IFERROR(D28,0))
C29: =IF(A29="","",COUNTIF($A$5:$H$14,A29)*25 + IFERROR(D29,0))
C30: =IF(A30="","",COUNTIF($A$5:$H$14,A30)*25 + IFERROR(D30,0))
C31: =IF(A31="","",COUNTIF($A$5:$H$14,A31)*25 + IFERROR(D31,0))
C32: =IF(A32="","",COUNTIF($A$5:$H$14,A32)*25 + IFERROR(D32,0))
